Workbook

Sheet Compile Sheet 
A1: S.N | B1: Resources | C1: Teams | D1: Designation | E1: S122 | F1: S123 | G1: S124 | H1: S125 | I1: S126 | J1: S127 | K1: S128 | L1: S129 | M1: S130 | N1: S131 | O1: S132 | P1: S133 | Q1: S134 | R1: S135 | S1: S136 | T1: S137 | U1: S138 | V1: S139 | W1: S140 | X1: S141 | Y1: Total | Z1: Average | AB1: Overall Rankings | AJ1: ="Last "&Sheet1!$G$1&" Sprints Rankings ("&Sheet1!$G$4&")" -> Last 6 Sprints Rankings (S133 – S138) | AR1: Helper: last-N window
AB2: S.N | AC2: Name | AD2: Designation | AE2: Sprints | AF2: Total Score | AG2: Avg Score | AH2: Overall Ranking | AJ2: S.N | AK2: Name | AL2: Designation | AM2: Team | AN2: Sprints | AO2: Avg Score | AP2: Overall Ranking | AR2: Last-N Avg | AS2: Last-N Sprints
B3: TEAM LEAD | AB3: TEAM LEAD | AJ3: TEAM LEAD
A4: 1 | B4: Bishal Stha | C4: Team Bravo | D4: Team Lead | E4: RUN | F4: RUN | G4: RUN | H4: 10 | I4: 9.2 | J4: 9 | K4: 9 | L4: 10 | M4: 8.33 | N4: 8.67 | O4: 9.4 | P4: 8.67 | Q4: 8.67 | R4: 6 | S4: 9.2 | T4: 9.6 | U4: ='[1]Team Bravo'!C6 -> 8.67 | Y4: =SUM(E4:X4) -> 124.41 | Z4: =IFERROR(AVERAGE(E4:X4),"-") -> 8.8864286 | AB4: 1 | AC4: {=INDEX(_xlfn.SORTBY($B$4:$B$9,IF(ISNUMBER($Z$4:$Z$9),$Z$4:$Z$9,-1),-1,$Y$4:$Y$9,-1),$AB4)} -> Niba Tandukar | AD4: =INDEX($D$4:$D$9,MATCH($AC4,$B$4:$B$9,0)) -> Team Lead | AE4: =COUNT(INDEX($E$4:$X$9,MATCH($AC4,$B$4:$B$9,0),0)) -> 10 | AF4: =INDEX($Y$4:$Y$9,MATCH($AC4,$B$4:$B$9,0)) -> 95.26 | AG4: =INDEX($Z$4:$Z$9,MATCH($AC4,$B$4:$B$9,0)) -> 9.526 | AH4: =RANK(AG4,$AG$4:$AG$57,0) -> 4 | AJ4: 1 | AK4: {=INDEX(_xlfn.SORTBY($B$4:$B$9,IF(ISNUMBER($AR$4:$AR$9),$AR$4:$AR$9,-1),-1,$AS$4:$AS$9,-1),$AJ4)} -> Niba Tandukar | AL4: =INDEX($D$4:$D$9,MATCH($AK4,$B$4:$B$9,0)) -> Team Lead | AM4: =INDEX($C$4:$C$9,MATCH($AK4,$B$4:$B$9,0)) -> DevOps | AN4: =INDEX($AS$4:$AS$9,MATCH($AK4,$B$4:$B$9,0)) -> 6 | AO4: =INDEX($AR$4:$AR$9,MATCH($AK4,$B$4:$B$9,0)) -> 9.5216667 | AP4: =IF(ISNUMBER(AO4),RANK(AO4,$AO$4:$AO$57,0),"-") -> 5 | AR4: =IF(ISNUMBER($A4),IFERROR(AVERAGE(INDEX($E4:$X4,MATCH(Sheet1!$G$3,$E$1:$X$1,0)):INDEX($E4:$X4,MATCH(Sheet1!$G$2,$E$1:$X$1,0))),"-"),"") -> 8.4683333 | AS4: =IF(ISNUMBER($A4),COUNT(INDEX($E4:$X4,MATCH(Sheet1!$G$3,$E$1:$X$1,0)):INDEX($E4:$X4,MATCH(Sheet1!$G$2,$E$1:$X$1,0))),"") -> 6
A5: 2 | B5: Niba Tandukar | C5: DevOps | D5: Team Lead | E5: N/A | F5: N/A | G5: N/A | H5: N/A | I5: N/A | J5: N/A | K5: N/A | L5: 8.33 | M5: 10 | N5: 10 | O5: 9.8 | P5: 8.33 | Q5: 9.8 | R5: 10 | S5: 9.8 | T5: 9.2 | U5: =[1]DevOps!C2 -> 10 | Y5: =SUM(E5:X5) -> 95.26 | Z5: =IFERROR(AVERAGE(E5:X5),"-") -> 9.526 | AB5: =AB4+1 -> 2 | AC5: {=INDEX(_xlfn.SORTBY($B$4:$B$9,IF(ISNUMBER($Z$4:$Z$9),$Z$4:$Z$9,-1),-1,$Y$4:$Y$9,-1),$AB5)} -> Bishal Stha | AD5: =INDEX($D$4:$D$9,MATCH($AC5,$B$4:$B$9,0)) -> Team Lead | AE5: =COUNT(INDEX($E$4:$X$9,MATCH($AC5,$B$4:$B$9,0),0)) -> 14 | AF5: =INDEX($Y$4:$Y$9,MATCH($AC5,$B$4:$B$9,0)) -> 124.41 | AG5: =INDEX($Z$4:$Z$9,MATCH($AC5,$B$4:$B$9,0)) -> 8.8864286 | AH5: =RANK(AG5,$AG$4:$AG$57,0) -> 11 | AJ5: =AJ4+1 -> 2 | AK5: {=INDEX(_xlfn.SORTBY($B$4:$B$9,IF(ISNUMBER($AR$4:$AR$9),$AR$4:$AR$9,-1),-1,$AS$4:$AS$9,-1),$AJ5)} -> Bishal Stha | AL5: =INDEX($D$4:$D$9,MATCH($AK5,$B$4:$B$9,0)) -> Team Lead | AM5: =INDEX($C$4:$C$9,MATCH($AK5,$B$4:$B$9,0)) -> Team Bravo | AN5: =INDEX($AS$4:$AS$9,MATCH($AK5,$B$4:$B$9,0)) -> 6 | AO5: =INDEX($AR$4:$AR$9,MATCH($AK5,$B$4:$B$9,0)) -> 8.4683333 | AP5: =IF(ISNUMBER(AO5),RANK(AO5,$AO$4:$AO$57,0),"-") -> 29 | AR5: =IF(ISNUMBER($A5),IFERROR(AVERAGE(INDEX($E5:$X5,MATCH(Sheet1!$G$3,$E$1:$X$1,0)):INDEX($E5:$X5,MATCH(Sheet1!$G$2,$E$1:$X$1,0))),"-"),"") -> 9.5216667 | AS5: =IF(ISNUMBER($A5),COUNT(INDEX($E5:$X5,MATCH(Sheet1!$G$3,$E$1:$X$1,0)):INDEX($E5:$X5,MATCH(Sheet1!$G$2,$E$1:$X$1,0))),"") -> 6
A6: 3 | B6: Dharma Gurung | C6: Blaze Warrior | D6: Team Lead | E6: 10 | F6: 8.67 | G6: 6.5 | H6: 8.33 | I6: 9 | J6: 6.5 | K6: 4.64 | L6: 9 | M6: 9 | N6: 8.33 | O6: 10 | P6: 7 | Q6: 9 | R6: 9 | S6: 8.33 | T6: 6.25 | U6: ='[1]Team Dharma'!C5 -> 7 | Y6: =SUM(E6:X6) -> 136.55 | Z6: =IFERROR(AVERAGE(E6:X6),"-") -> 8.0323529 | AB6: =AB5+1 -> 3 | AC6: {=INDEX(_xlfn.SORTBY($B$4:$B$9,IF(ISNUMBER($Z$4:$Z$9),$Z$4:$Z$9,-1),-1,$Y$4:$Y$9,-1),$AB6)} -> Dharma Gurung | AD6: =INDEX($D$4:$D$9,MATCH($AC6,$B$4:$B$9,0)) -> Team Lead | AE6: =COUNT(INDEX($E$4:$X$9,MATCH($AC6,$B$4:$B$9,0),0)) -> 17 | AF6: =INDEX($Y$4:$Y$9,MATCH($AC6,$B$4:$B$9,0)) -> 136.55 | AG6: =INDEX($Z$4:$Z$9,MATCH($AC6,$B$4:$B$9,0)) -> 8.0323529 | AH6: =RANK(AG6,$AG$4:$AG$57,0) -> 21 | AJ6: =AJ5+1 -> 3 | AK6: {=INDEX(_xlfn.SORTBY($B$4:$B$9,IF(ISNUMBER($AR$4:$AR$9),$AR$4:$AR$9,-1),-1,$AS$4:$AS$9,-1),$AJ6)} -> Bimal Sharma | AL6: =INDEX($D$4:$D$9,MATCH($AK6,$B$4:$B$9,0)) -> Team Lead | AM6: =INDEX($C$4:$C$9,MATCH($AK6,$B$4:$B$9,0)) -> Team Bimal | AN6: =INDEX($AS$4:$AS$9,MATCH($AK6,$B$4:$B$9,0)) -> 6 | AO6: =INDEX($AR$4:$AR$9,MATCH($AK6,$B$4:$B$9,0)) -> 7.8733333 | AP6: =IF(ISNUMBER(AO6),RANK(AO6,$AO$4:$AO$57,0),"-") -> 40 | AR6: =IF(ISNUMBER($A6),IFERROR(AVERAGE(INDEX($E6:$X6,MATCH(Sheet1!$G$3,$E$1:$X$1,0)):INDEX($E6:$X6,MATCH(Sheet1!$G$2,$E$1:$X$1,0))),"-"),"") -> 7.7633333 | AS6: =IF(ISNUMBER($A6),COUNT(INDEX($E6:$X6,MATCH(Sheet1!$G$3,$E$1:$X$1,0)):INDEX($E6:$X6,MATCH(Sheet1!$G$2,$E$1:$X$1,0))),"") -> 6
A7: 4 | B7: Sanjay Khadka | C7: Team Sanjay | D7: Team Lead | E7: 8.67 | F7: 10 | G7: 8.67 | H7: N/A | I7: 9.4 | J7: 7 | K7: 8.33 | L7: 6 | M7: 6 | N7: 9.2 | O7: 6.5 | P7: 8.33 | Q7: 8.33 | R7: 8.33 | S7: 6.5 | T7: 8.33 | U7: ='[1]Team Sanjay'!C5 -> 6.5 | Y7: =SUM(E7:X7) -> 126.09 | Z7: =IFERROR(AVERAGE(E7:X7),"-") -> 7.880625 | AB7: =AB6+1 -> 4 | AC7: {=INDEX(_xlfn.SORTBY($B$4:$B$9,IF(ISNUMBER($Z$4:$Z$9),$Z$4:$Z$9,-1),-1,$Y$4:$Y$9,-1),$AB7)} -> Sanjay Khadka | AD7: =INDEX($D$4:$D$9,MATCH($AC7,$B$4:$B$9,0)) -> Team Lead | AE7: =COUNT(INDEX($E$4:$X$9,MATCH($AC7,$B$4:$B$9,0),0)) -> 16 | AF7: =INDEX($Y$4:$Y$9,MATCH($AC7,$B$4:$B$9,0)) -> 126.09 | AG7: =INDEX($Z$4:$Z$9,MATCH($AC7,$B$4:$B$9,0)) -> 7.880625 | AH7: =RANK(AG7,$AG$4:$AG$57,0) -> 24 | AJ7: =AJ6+1 -> 4 | AK7: {=INDEX(_xlfn.SORTBY($B$4:$B$9,IF(ISNUMBER($AR$4:$AR$9),$AR$4:$AR$9,-1),-1,$AS$4:$AS$9,-1),$AJ7)} -> Dharma Gurung | AL7: =INDEX($D$4:$D$9,MATCH($AK7,$B$4:$B$9,0)) -> Team Lead | AM7: =INDEX($C$4:$C$9,MATCH($AK7,$B$4:$B$9,0)) -> Blaze Warrior | AN7: =INDEX($AS$4:$AS$9,MATCH($AK7,$B$4:$B$9,0)) -> 6 | AO7: =INDEX($AR$4:$AR$9,MATCH($AK7,$B$4:$B$9,0)) -> 7.7633333 | AP7: =IF(ISNUMBER(AO7),RANK(AO7,$AO$4:$AO$57,0),"-") -> 42 | AR7: =IF(ISNUMBER($A7),IFERROR(AVERAGE(INDEX($E7:$X7,MATCH(Sheet1!$G$3,$E$1:$X$1,0)):INDEX($E7:$X7,MATCH(Sheet1!$G$2,$E$1:$X$1,0))),"-"),"") -> 7.72 | AS7: =IF(ISNUMBER($A7),COUNT(INDEX($E7:$X7,MATCH(Sheet1!$G$3,$E$1:$X$1,0)):INDEX($E7:$X7,MATCH(Sheet1!$G$2,$E$1:$X$1,0))),"") -> 6
A8: 5 | B8: Bimal Sharma | C8: Team Bimal | D8: Team Lead | E8: 6.5 | F8: 8.33 | G8: 6.54 | H8: 9.2 | I8: 6.4 | J8: 7.03 | K8: 4.81 | L8: 5.47 | M8: 5.47 | N8: 8.33 | O8: 8.33 | P8: 6 | Q8: 9.4 | R8: 8.67 | S8: 9 | T8: 8.17 | U8: ='[1]Team Bimal'!C5 -> 6 | Y8: =SUM(E8:X8) -> 123.65 | Z8: =IFERROR(AVERAGE(E8:X8),"-") -> 7.2735294 | AB8: =AB7+1 -> 5 | AC8: {=INDEX(_xlfn.SORTBY($B$4:$B$9,IF(ISNUMBER($Z$4:$Z$9),$Z$4:$Z$9,-1),-1,$Y$4:$Y$9,-1),$AB8)} -> Bimal Sharma | AD8: =INDEX($D$4:$D$9,MATCH($AC8,$B$4:$B$9,0)) -> Team Lead | AE8: =COUNT(INDEX($E$4:$X$9,MATCH($AC8,$B$4:$B$9,0),0)) -> 17 | AF8: =INDEX($Y$4:$Y$9,MATCH($AC8,$B$4:$B$9,0)) -> 123.65 | AG8: =INDEX($Z$4:$Z$9,MATCH($AC8,$B$4:$B$9,0)) -> 7.2735294 | AH8: =RANK(AG8,$AG$4:$AG$57,0) -> 38 | AJ8: =AJ7+1 -> 5 | AK8: {=INDEX(_xlfn.SORTBY($B$4:$B$9,IF(ISNUMBER($AR$4:$AR$9),$AR$4:$AR$9,-1),-1,$AS$4:$AS$9,-1),$AJ8)} -> Sanjay Khadka | AL8: =INDEX($D$4:$D$9,MATCH($AK8,$B$4:$B$9,0)) -> Team Lead | AM8: =INDEX($C$4:$C$9,MATCH($AK8,$B$4:$B$9,0)) -> Team Sanjay | AN8: =INDEX($AS$4:$AS$9,MATCH($AK8,$B$4:$B$9,0)) -> 6 | AO8: =INDEX($AR$4:$AR$9,MATCH($AK8,$B$4:$B$9,0)) -> 7.72 | AP8: =IF(ISNUMBER(AO8),RANK(AO8,$AO$4:$AO$57,0),"-") -> 43 | AR8: =IF(ISNUMBER($A8),IFERROR(AVERAGE(INDEX($E8:$X8,MATCH(Sheet1!$G$3,$E$1:$X$1,0)):INDEX($E8:$X8,MATCH(Sheet1!$G$2,$E$1:$X$1,0))),"-"),"") -> 7.8733333 | AS8: =IF(ISNUMBER($A8),COUNT(INDEX($E8:$X8,MATCH(Sheet1!$G$3,$E$1:$X$1,0)):INDEX($E8:$X8,MATCH(Sheet1!$G$2,$E$1:$X$1,0))),"") -> 6
A9: 6 | B9: Bikash Bhandari | C9: Team Dhangadhi | D9: Team Lead | E9: N/A | F9: N/A | G9: N/A | H9: N/A | I9: N/A | J9: N/A | K9: N/A | L9: N/A | M9: 6 | N9: 7 | O9: 6 | P9: 9.4 | Q9: 6.5 | R9: 6 | S9: 6.5 | T9: 7 | U9: ='[1]Team Bikash'!C8 -> 7 | Y9: =SUM(E9:X9) -> 61.4 | Z9: =IFERROR(AVERAGE(E9:X9),"-") -> 6.8222222 | AB9: =AB8+1 -> 6 | AC9: {=INDEX(_xlfn.SORTBY($B$4:$B$9,IF(ISNUMBER($Z$4:$Z$9),$Z$4:$Z$9,-1),-1,$Y$4:$Y$9,-1),$AB9)} -> Bikash Bhandari | AD9: =INDEX($D$4:$D$9,MATCH($AC9,$B$4:$B$9,0)) -> Team Lead | AE9: =COUNT(INDEX($E$4:$X$9,MATCH($AC9,$B$4:$B$9,0),0)) -> 9 | AF9: =INDEX($Y$4:$Y$9,MATCH($AC9,$B$4:$B$9,0)) -> 61.4 | AG9: =INDEX($Z$4:$Z$9,MATCH($AC9,$B$4:$B$9,0)) -> 6.8222222 | AH9: =RANK(AG9,$AG$4:$AG$57,0) -> 45 | AJ9: =AJ8+1 -> 6 | AK9: {=INDEX(_xlfn.SORTBY($B$4:$B$9,IF(ISNUMBER($AR$4:$AR$9),$AR$4:$AR$9,-1),-1,$AS$4:$AS$9,-1),$AJ9)} -> Bikash Bhandari | AL9: =INDEX($D$4:$D$9,MATCH($AK9,$B$4:$B$9,0)) -> Team Lead | AM9: =INDEX($C$4:$C$9,MATCH($AK9,$B$4:$B$9,0)) -> Team Dhangadhi | AN9: =INDEX($AS$4:$AS$9,MATCH($AK9,$B$4:$B$9,0)) -> 6 | AO9: =INDEX($AR$4:$AR$9,MATCH($AK9,$B$4:$B$9,0)) -> 7.0666667 | AP9: =IF(ISNUMBER(AO9),RANK(AO9,$AO$4:$AO$57,0),"-") -> 47 | AR9: =IF(ISNUMBER($A9),IFERROR(AVERAGE(INDEX($E9:$X9,MATCH(Sheet1!$G$3,$E$1:$X$1,0)):INDEX($E9:$X9,MATCH(Sheet1!$G$2,$E$1:$X$1,0))),"-"),"") -> 7.0666667 | AS9: =IF(ISNUMBER($A9),COUNT(INDEX($E9:$X9,MATCH(Sheet1!$G$3,$E$1:$X$1,0)):INDEX($E9:$X9,MATCH(Sheet1!$G$2,$E$1:$X$1,0))),"") -> 6
B10: SSE | AB10: SSE | AJ10: SSE | AR10: =IF(ISNUMBER($A10),IFERROR(AVERAGE(INDEX($E10:$X10,MATCH(Sheet1!$G$3,$E$1:$X$1,0)):INDEX($E10:$X10,MATCH(Sheet1!$G$2,$E$1:$X$1,0))),"-"),"") | AS10: =IF(ISNUMBER($A10),COUNT(INDEX($E10:$X10,MATCH(Sheet1!$G$3,$E$1:$X$1,0)):INDEX($E10:$X10,MATCH(Sheet1!$G$2,$E$1:$X$1,0))),"")
A11: 1 | B11: Ram Chandra Dahal | C11: Run Team | D11: SSE | E11: 6.55 | F11: 7 | G11: 6.77 | H11: 8.9 | I11: 8.33 | J11: 9 | K11: 7.02 | L11: 7.14 | M11: N/A | N11: 8.33 | O11: 9.6 | P11: 8.33 | Q11: 7 | R11: 9.2 | S11: 8.67 | T11: 9.8 | U11: ='[1]Team Bimal'!C8 -> 9.7 | Y11: =SUM(E11:X11) -> 131.34 | Z11: =IFERROR(AVERAGE(E11:X11),"-") -> 8.20875 | AB11: 1 | AC11: {=INDEX(_xlfn.SORTBY($B$11:$B$17,IF(ISNUMBER($Z$11:$Z$17),$Z$11:$Z$17,-1),-1,$Y$11:$Y$17,-1),$AB11)} -> Susan Mool | AD11: =INDEX($D$11:$D$17,MATCH($AC11,$B$11:$B$17,0)) -> SSE | AE11: =COUNT(INDEX($E$11:$X$17,MATCH($AC11,$B$11:$B$17,0),0)) -> 3 | AF11: =INDEX($Y$11:$Y$17,MATCH($AC11,$B$11:$B$17,0)) -> 27.67 | AG11: =INDEX($Z$11:$Z$17,MATCH($AC11,$B$11:$B$17,0)) -> 9.2233333 | AH11: =RANK(AG11,$AG$4:$AG$57,0) -> 5 | AJ11: 1 | AK11: {=INDEX(_xlfn.SORTBY($B$11:$B$17,IF(ISNUMBER($AR$11:$AR$17),$AR$11:$AR$17,-1),-1,$AS$11:$AS$17,-1),$AJ11)} -> Susan Mool | AL11: =INDEX($D$11:$D$17,MATCH($AK11,$B$11:$B$17,0)) -> SSE | AM11: =INDEX($C$11:$C$17,MATCH($AK11,$B$11:$B$17,0)) -> Team Bimal | AN11: =INDEX($AS$11:$AS$17,MATCH($AK11,$B$11:$B$17,0)) -> 3 | AO11: =INDEX($AR$11:$AR$17,MATCH($AK11,$B$11:$B$17,0)) -> 9.2233333 | AP11: =IF(ISNUMBER(AO11),RANK(AO11,$AO$4:$AO$57,0),"-") -> 7 | AR11: =IF(ISNUMBER($A11),IFERROR(AVERAGE(INDEX($E11:$X11,MATCH(Sheet1!$G$3,$E$1:$X$1,0)):INDEX($E11:$X11,MATCH(Sheet1!$G$2,$E$1:$X$1,0))),"-"),"") -> 8.7833333 | AS11: =IF(ISNUMBER($A11),COUNT(INDEX($E11:$X11,MATCH(Sheet1!$G$3,$E$1:$X$1,0)):INDEX($E11:$X11,MATCH(Sheet1!$G$2,$E$1:$X$1,0))),"") -> 6
A12: 2 | B12: Abhinash Neupane | C12: Run Team | D12: SSE | E12: 8.28 | F12: 7 | G12: 7.64 | H12: RUN | I12: RUN | J12: 5.4 | K12: 6.4 | L12: 7.12 | M12: N/A | N12: 10 | O12: 10 | P12: 9.2 | Q12: 9.2 | R12: 7 | S12: 7 | T12: 9.2 | U12: ='[1]Run Team'!C4 -> 9.4 | Y12: =SUM(E12:X12) -> 112.84 | Z12: =IFERROR(AVERAGE(E12:X12),"-") -> 8.06 | AB12: =AB11+1 -> 2 | AC12: {=INDEX(_xlfn.SORTBY($B$11:$B$17,IF(ISNUMBER($Z$11:$Z$17),$Z$11:$Z$17,-1),-1,$Y$11:$Y$17,-1),$AB12)} -> Ravi Gupta | AD12: =INDEX($D$11:$D$17,MATCH($AC12,$B$11:$B$17,0)) -> SSE | AE12: =COUNT(INDEX($E$11:$X$17,MATCH($AC12,$B$11:$B$17,0),0)) -> 10 | AF12: =INDEX($Y$11:$Y$17,MATCH($AC12,$B$11:$B$17,0)) -> 86.77 | AG12: =INDEX($Z$11:$Z$17,MATCH($AC12,$B$11:$B$17,0)) -> 8.677 | AH12: =RANK(AG12,$AG$4:$AG$57,0) -> 12 | AJ12: =AJ11+1 -> 2 | AK12: {=INDEX(_xlfn.SORTBY($B$11:$B$17,IF(ISNUMBER($AR$11:$AR$17),$AR$11:$AR$17,-1),-1,$AS$11:$AS$17,-1),$AJ12)} -> Ravi Gupta | AL12: =INDEX($D$11:$D$17,MATCH($AK12,$B$11:$B$17,0)) -> SSE | AM12: =INDEX($C$11:$C$17,MATCH($AK12,$B$11:$B$17,0)) -> DevOps | AN12: =INDEX($AS$11:$AS$17,MATCH($AK12,$B$11:$B$17,0)) -> 6 | AO12: =INDEX($AR$11:$AR$17,MATCH($AK12,$B$11:$B$17,0)) -> 9.1116667 | AP12: =IF(ISNUMBER(AO12),RANK(AO12,$AO$4:$AO$57,0),"-") -> 11 | AR12: =IF(ISNUMBER($A12),IFERROR(AVERAGE(INDEX($E12:$X12,MATCH(Sheet1!$G$3,$E$1:$X$1,0)):INDEX($E12:$X12,MATCH(Sheet1!$G$2,$E$1:$X$1,0))),"-"),"") -> 8.5 | AS12: =IF(ISNUMBER($A12),COUNT(INDEX($E12:$X12,MATCH(Sheet1!$G$3,$E$1:$X$1,0)):INDEX($E12:$X12,MATCH(Sheet1!$G$2,$E$1:$X$1,0))),"") -> 6
A13: 3 | B13: Anuj Magar | C13: Team Bravo | D13: SSE | E13: RUN | F13: 6 | G13: RUN | H13: 9.55 | I13: 6.7 | J13: 5.95 | K13: 5.92 | L13: 7.01 | M13: 5.09 | N13: 9 | O13: 7 | P13: 8.85 | Q13: 8.95 | R13: 8.95 | S13: 9.55 | T13: 9.2 | U13: ='[1]Team Bravo'!C4 -> 8.95 | Y13: =SUM(E13:X13) -> 116.67 | Z13: =IFERROR(AVERAGE(E13:X13),"-") -> 7.778 | AB13: =AB12+1 -> 3 | AC13: {=INDEX(_xlfn.SORTBY($B$11:$B$17,IF(ISNUMBER($Z$11:$Z$17),$Z$11:$Z$17,-1),-1,$Y$11:$Y$17,-1),$AB13)} -> Ram Chandra Dahal | AD13: =INDEX($D$11:$D$17,MATCH($AC13,$B$11:$B$17,0)) -> SSE | AE13: =COUNT(INDEX($E$11:$X$17,MATCH($AC13,$B$11:$B$17,0),0)) -> 16 | AF13: =INDEX($Y$11:$Y$17,MATCH($AC13,$B$11:$B$17,0)) -> 131.34 | AG13: =INDEX($Z$11:$Z$17,MATCH($AC13,$B$11:$B$17,0)) -> 8.20875 | AH13: =RANK(AG13,$AG$4:$AG$57,0) -> 17 | AJ13: =AJ12+1 -> 3 | AK13: {=INDEX(_xlfn.SORTBY($B$11:$B$17,IF(ISNUMBER($AR$11:$AR$17),$AR$11:$AR$17,-1),-1,$AS$11:$AS$17,-1),$AJ13)} -> Anuj Magar | AL13: =INDEX($D$11:$D$17,MATCH($AK13,$B$11:$B$17,0)) -> SSE | AM13: =INDEX($C$11:$C$17,MATCH($AK13,$B$11:$B$17,0)) -> Team Bravo | AN13: =INDEX($AS$11:$AS$17,MATCH($AK13,$B$11:$B$17,0)) -> 6 | AO13: =INDEX($AR$11:$AR$17,MATCH($AK13,$B$11:$B$17,0)) -> 9.075 | AP13: =IF(ISNUMBER(AO13),RANK(AO13,$AO$4:$AO$57,0),"-") -> 13 | AR13: =IF(ISNUMBER($A13),IFERROR(AVERAGE(INDEX($E13:$X13,MATCH(Sheet1!$G$3,$E$1:$X$1,0)):INDEX($E13:$X13,MATCH(Sheet1!$G$2,$E$1:$X$1,0))),"-"),"") -> 9.075 | AS13: =IF(ISNUMBER($A13),COUNT(INDEX($E13:$X13,MATCH(Sheet1!$G$3,$E$1:$X$1,0)):INDEX($E13:$X13,MATCH(Sheet1!$G$2,$E$1:$X$1,0))),"") -> 6
A14: 4 | B14: Ravi Gupta | C14: DevOps | D14: SSE | E14: N/A | F14: N/A | G14: N/A | H14: N/A | I14: N/A | J14: N/A | K14: N/A | L14: 6.84 | M14: 5.86 | N14: 10 | O14: 9.4 | P14: 7 | Q14: 10 | R14: 8.67 | S14: 10 | T14: 10 | U14: =[1]DevOps!C3 -> 9 | Y14: =SUM(E14:X14) -> 86.77 | Z14: =IFERROR(AVERAGE(E14:X14),"-") -> 8.677 | AB14: =AB13+1 -> 4 | AC14: {=INDEX(_xlfn.SORTBY($B$11:$B$17,IF(ISNUMBER($Z$11:$Z$17),$Z$11:$Z$17,-1),-1,$Y$11:$Y$17,-1),$AB14)} -> Abhinash Neupane | AD14: =INDEX($D$11:$D$17,MATCH($AC14,$B$11:$B$17,0)) -> SSE | AE14: =COUNT(INDEX($E$11:$X$17,MATCH($AC14,$B$11:$B$17,0),0)) -> 14 | AF14: =INDEX($Y$11:$Y$17,MATCH($AC14,$B$11:$B$17,0)) -> 112.84 | AG14: =INDEX($Z$11:$Z$17,MATCH($AC14,$B$11:$B$17,0)) -> 8.06 | AH14: =RANK(AG14,$AG$4:$AG$57,0) -> 20 | AJ14: =AJ13+1 -> 4 | AK14: {=INDEX(_xlfn.SORTBY($B$11:$B$17,IF(ISNUMBER($AR$11:$AR$17),$AR$11:$AR$17,-1),-1,$AS$11:$AS$17,-1),$AJ14)} -> Ram Chandra Dahal | AL14: =INDEX($D$11:$D$17,MATCH($AK14,$B$11:$B$17,0)) -> SSE | AM14: =INDEX($C$11:$C$17,MATCH($AK14,$B$11:$B$17,0)) -> Run Team | AN14: =INDEX($AS$11:$AS$17,MATCH($AK14,$B$11:$B$17,0)) -> 6 | AO14: =INDEX($AR$11:$AR$17,MATCH($AK14,$B$11:$B$17,0)) -> 8.7833333 | AP14: =IF(ISNUMBER(AO14),RANK(AO14,$AO$4:$AO$57,0),"-") -> 18 | AR14: =IF(ISNUMBER($A14),IFERROR(AVERAGE(INDEX($E14:$X14,MATCH(Sheet1!$G$3,$E$1:$X$1,0)):INDEX($E14:$X14,MATCH(Sheet1!$G$2,$E$1:$X$1,0))),"-"),"") -> 9.1116667 | AS14: =IF(ISNUMBER($A14),COUNT(INDEX($E14:$X14,MATCH(Sheet1!$G$3,$E$1:$X$1,0)):INDEX($E14:$X14,MATCH(Sheet1!$G$2,$E$1:$X$1,0))),"") -> 6
A15: 5 | B15: Nirjal Dahal | C15: Blaze Warrior | D15: SSE | E15: 6.08 | F15: 5.87 | G15: 5.92 | H15: 6.58 | I15: 6 | J15: 5.84 | K15: 7 | L15: 5.43 | M15: 5.81 | N15: 7 | O15: 9.2 | P15: 9.2 | Q15: 9.35 | R15: 8.67 | S15: 9.2 | T15: 6.75 | U15: ='[1]Team Dharma'!C2 -> 8.67 | Y15: =SUM(E15:X15) -> 122.57 | Z15: =IFERROR(AVERAGE(E15:X15),"-") -> 7.21 | AB15: =AB14+1 -> 5 | AC15: {=INDEX(_xlfn.SORTBY($B$11:$B$17,IF(ISNUMBER($Z$11:$Z$17),$Z$11:$Z$17,-1),-1,$Y$11:$Y$17,-1),$AB15)} -> Anuj Magar | AD15: =INDEX($D$11:$D$17,MATCH($AC15,$B$11:$B$17,0)) -> SSE | AE15: =COUNT(INDEX($E$11:$X$17,MATCH($AC15,$B$11:$B$17,0),0)) -> 15 | AF15: =INDEX($Y$11:$Y$17,MATCH($AC15,$B$11:$B$17,0)) -> 116.67 | AG15: =INDEX($Z$11:$Z$17,MATCH($AC15,$B$11:$B$17,0)) -> 7.778 | AH15: =RANK(AG15,$AG$4:$AG$57,0) -> 27 | AJ15: =AJ14+1 -> 5 | AK15: {=INDEX(_xlfn.SORTBY($B$11:$B$17,IF(ISNUMBER($AR$11:$AR$17),$AR$11:$AR$17,-1),-1,$AS$11:$AS$17,-1),$AJ15)} -> Nirjal Dahal | AL15: =INDEX($D$11:$D$17,MATCH($AK15,$B$11:$B$17,0)) -> SSE | AM15: =INDEX($C$11:$C$17,MATCH($AK15,$B$11:$B$17,0)) -> Blaze Warrior | AN15: =INDEX($AS$11:$AS$17,MATCH($AK15,$B$11:$B$17,0)) -> 6 | AO15: =INDEX($AR$11:$AR$17,MATCH($AK15,$B$11:$B$17,0)) -> 8.64 | AP15: =IF(ISNUMBER(AO15),RANK(AO15,$AO$4:$AO$57,0),"-") -> 25 | AR15: =IF(ISNUMBER($A15),IFERROR(AVERAGE(INDEX($E15:$X15,MATCH(Sheet1!$G$3,$E$1:$X$1,0)):INDEX($E15:$X15,MATCH(Sheet1!$G$2,$E$1:$X$1,0))),"-"),"") -> 8.64 | AS15: =IF(ISNUMBER($A15),COUNT(INDEX($E15:$X15,MATCH(Sheet1!$G$3,$E$1:$X$1,0)):INDEX($E15:$X15,MATCH(Sheet1!$G$2,$E$1:$X$1,0))),"") -> 6
A16: 6 | B16: BK Krishna Magar | C16: Team Bravo | D16: SSE | E16: 5.14 | F16: 6.28 | G16: 4 | H16: 5.76 | I16: 9 | J16: 5.72 | K16: 6 | L16: 6.5 | M16: 7.16 | N16: 9.2 | O16: 9 | P16: 9.6 | Q16: 8.67 | R16: 8.33 | S16: 6.5 | T16: 8.33 | U16: ='[1]Team Bimal'!C6 -> 6 | Y16: =SUM(E16:X16) -> 121.19 | Z16: =IFERROR(AVERAGE(E16:X16),"-") -> 7.1288235 | AB16: =AB15+1 -> 6 | AC16: {=INDEX(_xlfn.SORTBY($B$11:$B$17,IF(ISNUMBER($Z$11:$Z$17),$Z$11:$Z$17,-1),-1,$Y$11:$Y$17,-1),$AB16)} -> Nirjal Dahal | AD16: =INDEX($D$11:$D$17,MATCH($AC16,$B$11:$B$17,0)) -> SSE | AE16: =COUNT(INDEX($E$11:$X$17,MATCH($AC16,$B$11:$B$17,0),0)) -> 17 | AF16: =INDEX($Y$11:$Y$17,MATCH($AC16,$B$11:$B$17,0)) -> 122.57 | AG16: =INDEX($Z$11:$Z$17,MATCH($AC16,$B$11:$B$17,0)) -> 7.21 | AH16: =RANK(AG16,$AG$4:$AG$57,0) -> 40 | AJ16: =AJ15+1 -> 6 | AK16: {=INDEX(_xlfn.SORTBY($B$11:$B$17,IF(ISNUMBER($AR$11:$AR$17),$AR$11:$AR$17,-1),-1,$AS$11:$AS$17,-1),$AJ16)} -> Abhinash Neupane | AL16: =INDEX($D$11:$D$17,MATCH($AK16,$B$11:$B$17,0)) -> SSE | AM16: =INDEX($C$11:$C$17,MATCH($AK16,$B$11:$B$17,0)) -> Run Team | AN16: =INDEX($AS$11:$AS$17,MATCH($AK16,$B$11:$B$17,0)) -> 6 | AO16: =INDEX($AR$11:$AR$17,MATCH($AK16,$B$11:$B$17,0)) -> 8.5 | AP16: =IF(ISNUMBER(AO16),RANK(AO16,$AO$4:$AO$57,0),"-") -> 27 | AR16: =IF(ISNUMBER($A16),IFERROR(AVERAGE(INDEX($E16:$X16,MATCH(Sheet1!$G$3,$E$1:$X$1,0)):INDEX($E16:$X16,MATCH(Sheet1!$G$2,$E$1:$X$1,0))),"-"),"") -> 7.905 | AS16: =IF(ISNUMBER($A16),COUNT(INDEX($E16:$X16,MATCH(Sheet1!$G$3,$E$1:$X$1,0)):INDEX($E16:$X16,MATCH(Sheet1!$G$2,$E$1:$X$1,0))),"") -> 6
A17: 7 | B17: Susan Mool | C17: Team Bimal | D17: SSE | E17: N/A | F17: N/A | G17: N/A | H17: N/A | I17: N/A | J17: N/A | K17: N/A | L17: N/A | M17: N/A | N17: N/A | O17: N/A | P17: N/A | Q17: N/A | R17: N/A | S17: 10 | T17: 9 | U17: ='[1]UI Team'!C2 -> 8.67 | Y17: =SUM(E17:X17) -> 27.67 | Z17: =IFERROR(AVERAGE(E17:X17),"-") -> 9.2233333 | AB17: =AB16+1 -> 7 | AC17: {=INDEX(_xlfn.SORTBY($B$11:$B$17,IF(ISNUMBER($Z$11:$Z$17),$Z$11:$Z$17,-1),-1,$Y$11:$Y$17,-1),$AB17)} -> BK Krishna Magar | AD17: =INDEX($D$11:$D$17,MATCH($AC17,$B$11:$B$17,0)) -> SSE | AE17: =COUNT(INDEX($E$11:$X$17,MATCH($AC17,$B$11:$B$17,0),0)) -> 17 | AF17: =INDEX($Y$11:$Y$17,MATCH($AC17,$B$11:$B$17,0)) -> 121.19 | AG17: =INDEX($Z$11:$Z$17,MATCH($AC17,$B$11:$B$17,0)) -> 7.1288235 | AH17: =RANK(AG17,$AG$4:$AG$57,0) -> 42 | AJ17: =AJ16+1 -> 7 | AK17: {=INDEX(_xlfn.SORTBY($B$11:$B$17,IF(ISNUMBER($AR$11:$AR$17),$AR$11:$AR$17,-1),-1,$AS$11:$AS$17,-1),$AJ17)} -> BK Krishna Magar | AL17: =INDEX($D$11:$D$17,MATCH($AK17,$B$11:$B$17,0)) -> SSE | AM17: =INDEX($C$11:$C$17,MATCH($AK17,$B$11:$B$17,0)) -> Team Bravo | AN17: =INDEX($AS$11:$AS$17,MATCH($AK17,$B$11:$B$17,0)) -> 6 | AO17: =INDEX($AR$11:$AR$17,MATCH($AK17,$B$11:$B$17,0)) -> 7.905 | AP17: =IF(ISNUMBER(AO17),RANK(AO17,$AO$4:$AO$57,0),"-") -> 37 | AR17: =IF(ISNUMBER($A17),IFERROR(AVERAGE(INDEX($E17:$X17,MATCH(Sheet1!$G$3,$E$1:$X$1,0)):INDEX($E17:$X17,MATCH(Sheet1!$G$2,$E$1:$X$1,0))),"-"),"") -> 9.2233333 | AS17: =IF(ISNUMBER($A17),COUNT(INDEX($E17:$X17,MATCH(Sheet1!$G$3,$E$1:$X$1,0)):INDEX($E17:$X17,MATCH(Sheet1!$G$2,$E$1:$X$1,0))),"") -> 3
AR18: =IF(ISNUMBER($A18),IFERROR(AVERAGE(INDEX($E18:$X18,MATCH(Sheet1!$G$3,$E$1:$X$1,0)):INDEX($E18:$X18,MATCH(Sheet1!$G$2,$E$1:$X$1,0))),"-"),"") | AS18: =IF(ISNUMBER($A18),COUNT(INDEX($E18:$X18,MATCH(Sheet1!$G$3,$E$1:$X$1,0)):INDEX($E18:$X18,MATCH(Sheet1!$G$2,$E$1:$X$1,0))),"")
B19: SE | AB19: SE | AJ19: SE | AR19: =IF(ISNUMBER($A19),IFERROR(AVERAGE(INDEX($E19:$X19,MATCH(Sheet1!$G$3,$E$1:$X$1,0)):INDEX($E19:$X19,MATCH(Sheet1!$G$2,$E$1:$X$1,0))),"-"),"") | AS19: =IF(ISNUMBER($A19),COUNT(INDEX($E19:$X19,MATCH(Sheet1!$G$3,$E$1:$X$1,0)):INDEX($E19:$X19,MATCH(Sheet1!$G$2,$E$1:$X$1,0))),"")
A20: 1 | B20: Shreeya Shakya | C20: Team Bravo | D20: SE | E20: 9.2 | F20: 6.95 | G20: 6.5 | H20: 8.7 | I20: 8.83 | J20: 10 | K20: 9.6 | L20: 7.68 | M20: 6.72 | N20: 9.2 | O20: 9.45 | P20: 9.95 | Q20: 9.1 | R20: 7.15 | S20: 7.45 | T20: 8.33 | U20: ='[1]Team Bravo'!C5 -> 10 | Y20: =SUM(E20:X20) -> 144.81 | Z20: =IFERROR(AVERAGE(E20:X20),"-") -> 8.5182353 | AB20: 1 | AC20: {=INDEX(_xlfn.SORTBY($B$20:$B$35,IF(ISNUMBER($Z$20:$Z$35),$Z$20:$Z$35,-1),-1,$Y$20:$Y$35,-1),$AB20)} -> Mandip Thapa | AD20: =INDEX($D$20:$D$35,MATCH($AC20,$B$20:$B$35,0)) -> SE | AE20: =COUNT(INDEX($E$20:$X$35,MATCH($AC20,$B$20:$B$35,0),0)) -> 1 | AF20: =INDEX($Y$20:$Y$35,MATCH($AC20,$B$20:$B$35,0)) -> 9 | AG20: =INDEX($Z$20:$Z$35,MATCH($AC20,$B$20:$B$35,0)) -> 9 | AH20: =RANK(AG20,$AG$4:$AG$57,0) -> 7 | AJ20: 1 | AK20: {=INDEX(_xlfn.SORTBY($B$20:$B$35,IF(ISNUMBER($AR$20:$AR$35),$AR$20:$AR$35,-1),-1,$AS$20:$AS$35,-1),$AJ20)} -> Sajjan Khanal | AL20: =INDEX($D$20:$D$35,MATCH($AK20,$B$20:$B$35,0)) -> SE | AM20: =INDEX($C$20:$C$35,MATCH($AK20,$B$20:$B$35,0)) -> DevOps | AN20: =INDEX($AS$20:$AS$35,MATCH($AK20,$B$20:$B$35,0)) -> 5 | AO20: =INDEX($AR$20:$AR$35,MATCH($AK20,$B$20:$B$35,0)) -> 9.8 | AP20: =IF(ISNUMBER(AO20),RANK(AO20,$AO$4:$AO$57,0),"-") -> 2 | AR20: =IF(ISNUMBER($A20),IFERROR(AVERAGE(INDEX($E20:$X20,MATCH(Sheet1!$G$3,$E$1:$X$1,0)):INDEX($E20:$X20,MATCH(Sheet1!$G$2,$E$1:$X$1,0))),"-"),"") -> 8.6633333 | AS20: =IF(ISNUMBER($A20),COUNT(INDEX($E20:$X20,MATCH(Sheet1!$G$3,$E$1:$X$1,0)):INDEX($E20:$X20,MATCH(Sheet1!$G$2,$E$1:$X$1,0))),"") -> 6
A21: 2 | B21: Sajjan Khanal | C21: DevOps | D21: SE | E21: N/A | F21: N/A | G21: N/A | H21: N/A | I21: N/A | J21: N/A | K21: N/A | L21: 7.31 | M21: 5.25 | N21: 10 | O21: 9.4 | P21: 9.4 | Q21: 10 | R21: 10 | S21: 10 | T21: 9.6 | Y21: =SUM(E21:X21) -> 80.96 | Z21: =IFERROR(AVERAGE(E21:X21),"-") -> 8.9955556 | AB21: =AB20+1 -> 2 | AC21: {=INDEX(_xlfn.SORTBY($B$20:$B$35,IF(ISNUMBER($Z$20:$Z$35),$Z$20:$Z$35,-1),-1,$Y$20:$Y$35,-1),$AB21)} -> Sajjan Khanal | AD21: =INDEX($D$20:$D$35,MATCH($AC21,$B$20:$B$35,0)) -> SE | AE21: =COUNT(INDEX($E$20:$X$35,MATCH($AC21,$B$20:$B$35,0),0)) -> 9 | AF21: =INDEX($Y$20:$Y$35,MATCH($AC21,$B$20:$B$35,0)) -> 80.96 | AG21: =INDEX($Z$20:$Z$35,MATCH($AC21,$B$20:$B$35,0)) -> 8.9955556 | AH21: =RANK(AG21,$AG$4:$AG$57,0) -> 8 | AJ21: =AJ20+1 -> 2 | AK21: {=INDEX(_xlfn.SORTBY($B$20:$B$35,IF(ISNUMBER($AR$20:$AR$35),$AR$20:$AR$35,-1),-1,$AS$20:$AS$35,-1),$AJ21)} -> Sagar Maharjan | AL21: =INDEX($D$20:$D$35,MATCH($AK21,$B$20:$B$35,0)) -> SE | AM21: =INDEX($C$20:$C$35,MATCH($AK21,$B$20:$B$35,0)) -> Blaze Warrior | AN21: =INDEX($AS$20:$AS$35,MATCH($AK21,$B$20:$B$35,0)) -> 6 | AO21: =INDEX($AR$20:$AR$35,MATCH($AK21,$B$20:$B$35,0)) -> 9.1616667 | AP21: =IF(ISNUMBER(AO21),RANK(AO21,$AO$4:$AO$57,0),"-") -> 9 | AR21: =IF(ISNUMBER($A21),IFERROR(AVERAGE(INDEX($E21:$X21,MATCH(Sheet1!$G$3,$E$1:$X$1,0)):INDEX($E21:$X21,MATCH(Sheet1!$G$2,$E$1:$X$1,0))),"-"),"") -> 9.8 | AS21: =IF(ISNUMBER($A21),COUNT(INDEX($E21:$X21,MATCH(Sheet1!$G$3,$E$1:$X$1,0)):INDEX($E21:$X21,MATCH(Sheet1!$G$2,$E$1:$X$1,0))),"") -> 5
A22: 3 | B22: Susmita Parajuli | C22: Blaze Warrior | D22: SE | E22: 7.21 | F22: 7.25 | G22: 6.8 | H22: 6.3 | I22: 7.28 | J22: 6.8 | K22: 7.4 | L22: 8.63 | M22: 5.9 | N22: 8.43 | O22: 8.68 | P22: 9.4 | Q22: 6.7 | R22: 9.35 | S22: 9.35 | T22: 6.75 | U22: ='[1]Team Dharma'!C4 -> 8.63 | Y22: =SUM(E22:X22) -> 130.86 | Z22: =IFERROR(AVERAGE(E22:X22),"-") -> 7.6976471 | AB22: =AB21+1 -> 3 | AC22: {=INDEX(_xlfn.SORTBY($B$20:$B$35,IF(ISNUMBER($Z$20:$Z$35),$Z$20:$Z$35,-1),-1,$Y$20:$Y$35,-1),$AB22)} -> Jeevan Joshi | AD22: =INDEX($D$20:$D$35,MATCH($AC22,$B$20:$B$35,0)) -> SE | AE22: =COUNT(INDEX($E$20:$X$35,MATCH($AC22,$B$20:$B$35,0),0)) -> 9 | AF22: =INDEX($Y$20:$Y$35,MATCH($AC22,$B$20:$B$35,0)) -> 80.8 | AG22: =INDEX($Z$20:$Z$35,MATCH($AC22,$B$20:$B$35,0)) -> 8.9777778 | AH22: =RANK(AG22,$AG$4:$AG$57,0) -> 9 | AJ22: =AJ21+1 -> 3 | AK22: {=INDEX(_xlfn.SORTBY($B$20:$B$35,IF(ISNUMBER($AR$20:$AR$35),$AR$20:$AR$35,-1),-1,$AS$20:$AS$35,-1),$AJ22)} -> Jeevan Joshi | AL22: =INDEX($D$20:$D$35,MATCH($AK22,$B$20:$B$35,0)) -> SE | AM22: =INDEX($C$20:$C$35,MATCH($AK22,$B$20:$B$35,0)) -> Run Team | AN22: =INDEX($AS$20:$AS$35,MATCH($AK22,$B$20:$B$35,0)) -> 6 | AO22: =INDEX($AR$20:$AR$35,MATCH($AK22,$B$20:$B$35,0)) -> 9.1 | AP22: =IF(ISNUMBER(AO22),RANK(AO22,$AO$4:$AO$57,0),"-") -> 12 | AR22: =IF(ISNUMBER($A22),IFERROR(AVERAGE(INDEX($E22:$X22,MATCH(Sheet1!$G$3,$E$1:$X$1,0)):INDEX($E22:$X22,MATCH(Sheet1!$G$2,$E$1:$X$1,0))),"-"),"") -> 8.3633333 | AS22: =IF(ISNUMBER($A22),COUNT(INDEX($E22:$X22,MATCH(Sheet1!$G$3,$E$1:$X$1,0)):INDEX($E22:$X22,MATCH(Sheet1!$G$2,$E$1:$X$1,0))),"") -> 6
A23: 4 | B23: Rashik Shrestha | C23: Run Team | D23: SE | E23: 9.6 | F23: 6.84 | G23: 7 | H23: 6.25 | I23: 9 | J23: 9.2 | K23: RUN | L23: 7 | M23: N/A | N23: 8.33 | O23: 9 | P23: 8.33 | Q23: 7 | R23: 9.2 | S23: 9.4 | T23: 9.2 | U23: ='[1]Run Team'!C5 -> 9 | Y23: =SUM(E23:X23) -> 124.35 | Z23: =IFERROR(AVERAGE(E23:X23),"-") -> 8.29 | AB23: =AB22+1 -> 4 | AC23: {=INDEX(_xlfn.SORTBY($B$20:$B$35,IF(ISNUMBER($Z$20:$Z$35),$Z$20:$Z$35,-1),-1,$Y$20:$Y$35,-1),$AB23)} -> Shreeya Shakya | AD23: =INDEX($D$20:$D$35,MATCH($AC23,$B$20:$B$35,0)) -> SE | AE23: =COUNT(INDEX($E$20:$X$35,MATCH($AC23,$B$20:$B$35,0),0)) -> 17 | AF23: =INDEX($Y$20:$Y$35,MATCH($AC23,$B$20:$B$35,0)) -> 144.81 | AG23: =INDEX($Z$20:$Z$35,MATCH($AC23,$B$20:$B$35,0)) -> 8.5182353 | AH23: =RANK(AG23,$AG$4:$AG$57,0) -> 14 | AJ23: =AJ22+1 -> 4 | AK23: {=INDEX(_xlfn.SORTBY($B$20:$B$35,IF(ISNUMBER($AR$20:$AR$35),$AR$20:$AR$35,-1),-1,$AS$20:$AS$35,-1),$AJ23)} -> Mandip Thapa | AL23: =INDEX($D$20:$D$35,MATCH($AK23,$B$20:$B$35,0)) -> SE | AM23: =INDEX($C$20:$C$35,MATCH($AK23,$B$20:$B$35,0)) -> DevOps | AN23: =INDEX($AS$20:$AS$35,MATCH($AK23,$B$20:$B$35,0)) -> 1 | AO23: =INDEX($AR$20:$AR$35,MATCH($AK23,$B$20:$B$35,0)) -> 9 | AP23: =IF(ISNUMBER(AO23),RANK(AO23,$AO$4:$AO$57,0),"-") -> 14 | AR23: =IF(ISNUMBER($A23),IFERROR(AVERAGE(INDEX($E23:$X23,MATCH(Sheet1!$G$3,$E$1:$X$1,0)):INDEX($E23:$X23,MATCH(Sheet1!$G$2,$E$1:$X$1,0))),"-"),"") -> 8.6883333 | AS23: =IF(ISNUMBER($A23),COUNT(INDEX($E23:$X23,MATCH(Sheet1!$G$3,$E$1:$X$1,0)):INDEX($E23:$X23,MATCH(Sheet1!$G$2,$E$1:$X$1,0))),"") -> 6
A24: 5 | B24: Aashish Katwal | C24: Team Bravo | D24: SE | E24: 7.7 | F24: 7.3 | G24: 8.33 | H24: 4.49 | I24: 6.5 | J24: 6.36 | K24: 6.95 | L24: 8.33 | M24: 5.85 | N24: 7 | O24: 9.15 | P24: 9.7 | Q24: 8.9 | R24: 7 | S24: 8.33 | T24: 8.67 | U24: ='[1]Team Bravo'!C7 -> 8.33 | Y24: =SUM(E24:X24) -> 128.89 | Z24: =IFERROR(AVERAGE(E24:X24),"-") -> 7.5817647 | AB24: =AB23+1 -> 5 | AC24: {=INDEX(_xlfn.SORTBY($B$20:$B$35,IF(ISNUMBER($Z$20:$Z$35),$Z$20:$Z$35,-1),-1,$Y$20:$Y$35,-1),$AB24)} -> Rashik Shrestha | AD24: =INDEX($D$20:$D$35,MATCH($AC24,$B$20:$B$35,0)) -> SE | AE24: =COUNT(INDEX($E$20:$X$35,MATCH($AC24,$B$20:$B$35,0),0)) -> 15 | AF24: =INDEX($Y$20:$Y$35,MATCH($AC24,$B$20:$B$35,0)) -> 124.35 | AG24: =INDEX($Z$20:$Z$35,MATCH($AC24,$B$20:$B$35,0)) -> 8.29 | AH24: =RANK(AG24,$AG$4:$AG$57,0) -> 16 | AJ24: =AJ23+1 -> 5 | AK24: {=INDEX(_xlfn.SORTBY($B$20:$B$35,IF(ISNUMBER($AR$20:$AR$35),$AR$20:$AR$35,-1),-1,$AS$20:$AS$35,-1),$AJ24)} -> Sayara Dangol | AL24: =INDEX($D$20:$D$35,MATCH($AK24,$B$20:$B$35,0)) -> SE | AM24: =INDEX($C$20:$C$35,MATCH($AK24,$B$20:$B$35,0)) -> Team Bimal | AN24: =INDEX($AS$20:$AS$35,MATCH($AK24,$B$20:$B$35,0)) -> 6 | AO24: =INDEX($AR$20:$AR$35,MATCH($AK24,$B$20:$B$35,0)) -> 8.9533333 | AP24: =IF(ISNUMBER(AO24),RANK(AO24,$AO$4:$AO$57,0),"-") -> 15 | AR24: =IF(ISNUMBER($A24),IFERROR(AVERAGE(INDEX($E24:$X24,MATCH(Sheet1!$G$3,$E$1:$X$1,0)):INDEX($E24:$X24,MATCH(Sheet1!$G$2,$E$1:$X$1,0))),"-"),"") -> 8.4883333 | AS24: =IF(ISNUMBER($A24),COUNT(INDEX($E24:$X24,MATCH(Sheet1!$G$3,$E$1:$X$1,0)):INDEX($E24:$X24,MATCH(Sheet1!$G$2,$E$1:$X$1,0))),"") -> 6
A25: 6 | B25: Sagar Maharjan | C25: Blaze Warrior | D25: SE | E25: 6.48 | F25: 8.33 | G25: 6.45 | H25: 5.48 | I25: 5.81 | J25: 7.09 | K25: 7 | L25: 6.45 | M25: 6.5 | N25: 8.62 | O25: 9.85 | P25: 9.1 | Q25: 9.4 | R25: 9.05 | S25: 8.95 | T25: 9.8 | U25: ='[1]Team Dharma'!C3 -> 8.67 | Y25: =SUM(E25:X25) -> 133.03 | Z25: =IFERROR(AVERAGE(E25:X25),"-") -> 7.8252941 | AB25: =AB24+1 -> 6 | AC25: {=INDEX(_xlfn.SORTBY($B$20:$B$35,IF(ISNUMBER($Z$20:$Z$35),$Z$20:$Z$35,-1),-1,$Y$20:$Y$35,-1),$AB25)} -> Prajjwal Pandey | AD25: =INDEX($D$20:$D$35,MATCH($AC25,$B$20:$B$35,0)) -> SE | AE25: =COUNT(INDEX($E$20:$X$35,MATCH($AC25,$B$20:$B$35,0),0)) -> 7 | AF25: =INDEX($Y$20:$Y$35,MATCH($AC25,$B$20:$B$35,0)) -> 56.53 | AG25: =INDEX($Z$20:$Z$35,MATCH($AC25,$B$20:$B$35,0)) -> 8.0757143 | AH25: =RANK(AG25,$AG$4:$AG$57,0) -> 19 | AJ25: =AJ24+1 -> 6 | AK25: {=INDEX(_xlfn.SORTBY($B$20:$B$35,IF(ISNUMBER($AR$20:$AR$35),$AR$20:$AR$35,-1),-1,$AS$20:$AS$35,-1),$AJ25)} -> Ankit Belal | AL25: =INDEX($D$20:$D$35,MATCH($AK25,$B$20:$B$35,0)) -> SE | AM25: =INDEX($C$20:$C$35,MATCH($AK25,$B$20:$B$35,0)) -> Team Dhangadhi | AN25: =INDEX($AS$20:$AS$35,MATCH($AK25,$B$20:$B$35,0)) -> 6 | AO25: =INDEX($AR$20:$AR$35,MATCH($AK25,$B$20:$B$35,0)) -> 8.745 | AP25: =IF(ISNUMBER(AO25),RANK(AO25,$AO$4:$AO$57,0),"-") -> 19 | AR25: =IF(ISNUMBER($A25),IFERROR(AVERAGE(INDEX($E25:$X25,MATCH(Sheet1!$G$3,$E$1:$X$1,0)):INDEX($E25:$X25,MATCH(Sheet1!$G$2,$E$1:$X$1,0))),"-"),"") -> 9.1616667 | AS25: =IF(ISNUMBER($A25),COUNT(INDEX($E25:$X25,MATCH(Sheet1!$G$3,$E$1:$X$1,0)):INDEX($E25:$X25,MATCH(Sheet1!$G$2,$E$1:$X$1,0))),"") -> 6
A26: 7 | B26: Sayara Dangol | C26: Team Bimal | D26: SE | E26: N/A | F26: N/A | G26: N/A | H26: 5.19 | I26: 8.17 | J26: 6.5 | K26: 6.49 | L26: 6.03 | M26: 8.33 | N26: 6 | O26: 6.85 | P26: 9.8 | Q26: 8.33 | R26: 8.62 | S26: 9.6 | T26: 8.33 | U26: ='[1]UI Team'!C3 -> 9.04 | Y26: =SUM(E26:X26) -> 107.28 | Z26: =IFERROR(AVERAGE(E26:X26),"-") -> 7.6628571 | AB26: =AB25+1 -> 7 | AC26: {=INDEX(_xlfn.SORTBY($B$20:$B$35,IF(ISNUMBER($Z$20:$Z$35),$Z$20:$Z$35,-1),-1,$Y$20:$Y$35,-1),$AB26)} -> Agrim Paneru | AD26: =INDEX($D$20:$D$35,MATCH($AC26,$B$20:$B$35,0)) -> SE | AE26: =COUNT(INDEX($E$20:$X$35,MATCH($AC26,$B$20:$B$35,0),0)) -> 6 | AF26: =INDEX($Y$20:$Y$35,MATCH($AC26,$B$20:$B$35,0)) -> 47.91 | AG26: =INDEX($Z$20:$Z$35,MATCH($AC26,$B$20:$B$35,0)) -> 7.985 | AH26: =RANK(AG26,$AG$4:$AG$57,0) -> 22 | AJ26: =AJ25+1 -> 7 | AK26: {=INDEX(_xlfn.SORTBY($B$20:$B$35,IF(ISNUMBER($AR$20:$AR$35),$AR$20:$AR$35,-1),-1,$AS$20:$AS$35,-1),$AJ26)} -> Rashik Shrestha | AL26: =INDEX($D$20:$D$35,MATCH($AK26,$B$20:$B$35,0)) -> SE | AM26: =INDEX($C$20:$C$35,MATCH($AK26,$B$20:$B$35,0)) -> Run Team | AN26: =INDEX($AS$20:$AS$35,MATCH($AK26,$B$20:$B$35,0)) -> 6 | AO26: =INDEX($AR$20:$AR$35,MATCH($AK26,$B$20:$B$35,0)) -> 8.6883333 | AP26: =IF(ISNUMBER(AO26),RANK(AO26,$AO$4:$AO$57,0),"-") -> 20 | AR26: =IF(ISNUMBER($A26),IFERROR(AVERAGE(INDEX($E26:$X26,MATCH(Sheet1!$G$3,$E$1:$X$1,0)):INDEX($E26:$X26,MATCH(Sheet1!$G$2,$E$1:$X$1,0))),"-"),"") -> 8.9533333 | AS26: =IF(ISNUMBER($A26),COUNT(INDEX($E26:$X26,MATCH(Sheet1!$G$3,$E$1:$X$1,0)):INDEX($E26:$X26,MATCH(Sheet1!$G$2,$E$1:$X$1,0))),"") -> 6
A27: 8 | B27: Jeevan Joshi | C27: Run Team | D27: SE | E27: RUN | F27: RUN | G27: RUN | H27: RUN | I27: RUN | J27: RUN | K27: RUN | L27: 6.4 | M27: N/A | N27: 9.8 | O27: 10 | P27: 9 | Q27: 10 | R27: 9.2 | S27: 8.33 | T27: 8.67 | U27: ='[1]Run Team'!C2 -> 9.4 | Y27: =SUM(E27:X27) -> 80.8 | Z27: =IFERROR(AVERAGE(E27:X27),"-") -> 8.9777778 | AB27: =AB26+1 -> 8 | AC27: {=INDEX(_xlfn.SORTBY($B$20:$B$35,IF(ISNUMBER($Z$20:$Z$35),$Z$20:$Z$35,-1),-1,$Y$20:$Y$35,-1),$AB27)} -> Sagar Maharjan | AD27: =INDEX($D$20:$D$35,MATCH($AC27,$B$20:$B$35,0)) -> SE | AE27: =COUNT(INDEX($E$20:$X$35,MATCH($AC27,$B$20:$B$35,0),0)) -> 17 | AF27: =INDEX($Y$20:$Y$35,MATCH($AC27,$B$20:$B$35,0)) -> 133.03 | AG27: =INDEX($Z$20:$Z$35,MATCH($AC27,$B$20:$B$35,0)) -> 7.8252941 | AH27: =RANK(AG27,$AG$4:$AG$57,0) -> 26 | AJ27: =AJ26+1 -> 8 | AK27: {=INDEX(_xlfn.SORTBY($B$20:$B$35,IF(ISNUMBER($AR$20:$AR$35),$AR$20:$AR$35,-1),-1,$AS$20:$AS$35,-1),$AJ27)} -> Shreeya Shakya | AL27: =INDEX($D$20:$D$35,MATCH($AK27,$B$20:$B$35,0)) -> SE | AM27: =INDEX($C$20:$C$35,MATCH($AK27,$B$20:$B$35,0)) -> Team Bravo | AN27: =INDEX($AS$20:$AS$35,MATCH($AK27,$B$20:$B$35,0)) -> 6 | AO27: =INDEX($AR$20:$AR$35,MATCH($AK27,$B$20:$B$35,0)) -> 8.6633333 | AP27: =IF(ISNUMBER(AO27),RANK(AO27,$AO$4:$AO$57,0),"-") -> 24 | AR27: =IF(ISNUMBER($A27),IFERROR(AVERAGE(INDEX($E27:$X27,MATCH(Sheet1!$G$3,$E$1:$X$1,0)):INDEX($E27:$X27,MATCH(Sheet1!$G$2,$E$1:$X$1,0))),"-"),"") -> 9.1 | AS27: =IF(ISNUMBER($A27),COUNT(INDEX($E27:$X27,MATCH(Sheet1!$G$3,$E$1:$X$1,0)):INDEX($E27:$X27,MATCH(Sheet1!$G$2,$E$1:$X$1,0))),"") -> 6
A28: 9 | B28: Ankit Belal | C28: Team Dhangadhi | D28: SE | E28: 3.75 | F28: 8.17 | G28: 6.5 | H28: N/A | I28: N/A | J28: N/A | K28: 6.87 | L28: 6.63 | M28: 6 | N28: 6 | O28: 7 | P28: 9 | Q28: 10 | R28: 9.8 | S28: 6 | T28: 9 | U28: ='[1]Run Team'!C6 -> 8.67 | Y28: =SUM(E28:X28) -> 103.39 | Z28: =IFERROR(AVERAGE(E28:X28),"-") -> 7.385 | AB28: =AB27+1 -> 9 | AC28: {=INDEX(_xlfn.SORTBY($B$20:$B$35,IF(ISNUMBER($Z$20:$Z$35),$Z$20:$Z$35,-1),-1,$Y$20:$Y$35,-1),$AB28)} -> Susmita Parajuli | AD28: =INDEX($D$20:$D$35,MATCH($AC28,$B$20:$B$35,0)) -> SE | AE28: =COUNT(INDEX($E$20:$X$35,MATCH($AC28,$B$20:$B$35,0),0)) -> 17 | AF28: =INDEX($Y$20:$Y$35,MATCH($AC28,$B$20:$B$35,0)) -> 130.86 | AG28: =INDEX($Z$20:$Z$35,MATCH($AC28,$B$20:$B$35,0)) -> 7.6976471 | AH28: =RANK(AG28,$AG$4:$AG$57,0) -> 29 | AJ28: =AJ27+1 -> 9 | AK28: {=INDEX(_xlfn.SORTBY($B$20:$B$35,IF(ISNUMBER($AR$20:$AR$35),$AR$20:$AR$35,-1),-1,$AS$20:$AS$35,-1),$AJ28)} -> Aashish Katwal | AL28: =INDEX($D$20:$D$35,MATCH($AK28,$B$20:$B$35,0)) -> SE | AM28: =INDEX($C$20:$C$35,MATCH($AK28,$B$20:$B$35,0)) -> Team Bravo | AN28: =INDEX($AS$20:$AS$35,MATCH($AK28,$B$20:$B$35,0)) -> 6 | AO28: =INDEX($AR$20:$AR$35,MATCH($AK28,$B$20:$B$35,0)) -> 8.4883333 | AP28: =IF(ISNUMBER(AO28),RANK(AO28,$AO$4:$AO$57,0),"-") -> 28 | AR28: =IF(ISNUMBER($A28),IFERROR(AVERAGE(INDEX($E28:$X28,MATCH(Sheet1!$G$3,$E$1:$X$1,0)):INDEX($E28:$X28,MATCH(Sheet1!$G$2,$E$1:$X$1,0))),"-"),"") -> 8.745 | AS28: =IF(ISNUMBER($A28),COUNT(INDEX($E28:$X28,MATCH(Sheet1!$G$3,$E$1:$X$1,0)):INDEX($E28:$X28,MATCH(Sheet1!$G$2,$E$1:$X$1,0))),"") -> 6
A29: 10 | B29: Anish Gho Shrestha | C29: Team Bimal | D29: SE | E29: 6 | F29: 5.33 | G29: 5.15 | H29: 6.21 | I29: 5.33 | J29: 6.29 | K29: 4.98 | L29: 6.5 | M29: 6.65 | N29: 6.3 | O29: 8.67 | P29: 10 | Q29: 9.35 | R29: 8.62 | S29: 7 | T29: 7 | U29: ='[1]Team Bimal'!C4 -> 6.75 | Y29: =SUM(E29:X29) -> 116.13 | Z29: =IFERROR(AVERAGE(E29:X29),"-") -> 6.8311765 | AB29: =AB28+1 -> 10 | AC29: {=INDEX(_xlfn.SORTBY($B$20:$B$35,IF(ISNUMBER($Z$20:$Z$35),$Z$20:$Z$35,-1),-1,$Y$20:$Y$35,-1),$AB29)} -> Anmol Chalise | AD29: =INDEX($D$20:$D$35,MATCH($AC29,$B$20:$B$35,0)) -> SE | AE29: =COUNT(INDEX($E$20:$X$35,MATCH($AC29,$B$20:$B$35,0),0)) -> 3 | AF29: =INDEX($Y$20:$Y$35,MATCH($AC29,$B$20:$B$35,0)) -> 23.06 | AG29: =INDEX($Z$20:$Z$35,MATCH($AC29,$B$20:$B$35,0)) -> 7.6866667 | AH29: =RANK(AG29,$AG$4:$AG$57,0) -> 30 | AJ29: =AJ28+1 -> 10 | AK29: {=INDEX(_xlfn.SORTBY($B$20:$B$35,IF(ISNUMBER($AR$20:$AR$35),$AR$20:$AR$35,-1),-1,$AS$20:$AS$35,-1),$AJ29)} -> Prajjwal Pandey | AL29: =INDEX($D$20:$D$35,MATCH($AK29,$B$20:$B$35,0)) -> SE | AM29: =INDEX($C$20:$C$35,MATCH($AK29,$B$20:$B$35,0)) -> Team Sanjay | AN29: =INDEX($AS$20:$AS$35,MATCH($AK29,$B$20:$B$35,0)) -> 6 | AO29: =INDEX($AR$20:$AR$35,MATCH($AK29,$B$20:$B$35,0)) -> 8.4216667 | AP29: =IF(ISNUMBER(AO29),RANK(AO29,$AO$4:$AO$57,0),"-") -> 30 | AR29: =IF(ISNUMBER($A29),IFERROR(AVERAGE(INDEX($E29:$X29,MATCH(Sheet1!$G$3,$E$1:$X$1,0)):INDEX($E29:$X29,MATCH(Sheet1!$G$2,$E$1:$X$1,0))),"-"),"") -> 8.12 | AS29: =IF(ISNUMBER($A29),COUNT(INDEX($E29:$X29,MATCH(Sheet1!$G$3,$E$1:$X$1,0)):INDEX($E29:$X29,MATCH(Sheet1!$G$2,$E$1:$X$1,0))),"") -> 6
A30: 11 | B30: Suyog Acharya | C30: Blaze Warrior | D30: SE | E30: 7 | F30: 6.1 | G30: 6 | H30: 5.96 | I30: 8.62 | J30: 4.69 | K30: 4.5 | L30: 5.63 | M30: 4.75 | N30: 6.5 | O30: 8.28 | P30: 8.33 | Q30: 8.28 | R30: 8.33 | S30: 9 | T30: 6.45 | U30: ='[1]Team Dharma'!C6 -> 7 | Y30: =SUM(E30:X30) -> 115.42 | Z30: =IFERROR(AVERAGE(E30:X30),"-") -> 6.7894118 | AB30: =AB29+1 -> 11 | AC30: {=INDEX(_xlfn.SORTBY($B$20:$B$35,IF(ISNUMBER($Z$20:$Z$35),$Z$20:$Z$35,-1),-1,$Y$20:$Y$35,-1),$AB30)} -> Sayara Dangol | AD30: =INDEX($D$20:$D$35,MATCH($AC30,$B$20:$B$35,0)) -> SE | AE30: =COUNT(INDEX($E$20:$X$35,MATCH($AC30,$B$20:$B$35,0),0)) -> 14 | AF30: =INDEX($Y$20:$Y$35,MATCH($AC30,$B$20:$B$35,0)) -> 107.28 | AG30: =INDEX($Z$20:$Z$35,MATCH($AC30,$B$20:$B$35,0)) -> 7.6628571 | AH30: =RANK(AG30,$AG$4:$AG$57,0) -> 31 | AJ30: =AJ29+1 -> 11 | AK30: {=INDEX(_xlfn.SORTBY($B$20:$B$35,IF(ISNUMBER($AR$20:$AR$35),$AR$20:$AR$35,-1),-1,$AS$20:$AS$35,-1),$AJ30)} -> Susmita Parajuli | AL30: =INDEX($D$20:$D$35,MATCH($AK30,$B$20:$B$35,0)) -> SE | AM30: =INDEX($C$20:$C$35,MATCH($AK30,$B$20:$B$35,0)) -> Blaze Warrior | AN30: =INDEX($AS$20:$AS$35,MATCH($AK30,$B$20:$B$35,0)) -> 6 | AO30: =INDEX($AR$20:$AR$35,MATCH($AK30,$B$20:$B$35,0)) -> 8.3633333 | AP30: =IF(ISNUMBER(AO30),RANK(AO30,$AO$4:$AO$57,0),"-") -> 31 | AR30: =IF(ISNUMBER($A30),IFERROR(AVERAGE(INDEX($E30:$X30,MATCH(Sheet1!$G$3,$E$1:$X$1,0)):INDEX($E30:$X30,MATCH(Sheet1!$G$2,$E$1:$X$1,0))),"-"),"") -> 7.8983333 | AS30: =IF(ISNUMBER($A30),COUNT(INDEX($E30:$X30,MATCH(Sheet1!$G$3,$E$1:$X$1,0)):INDEX($E30:$X30,MATCH(Sheet1!$G$2,$E$1:$X$1,0))),"") -> 6
A31: 12 | B31: Aayush Puri | C31: Team Sanjay | D31: SE | E31: N/A | F31: N/A | G31: N/A | H31: N/A | I31: N/A | J31: N/A | K31: N/A | L31: N/A | M31: N/A | N31: 8.33 | O31: 8.33 | P31: 8.33 | Q31: 9.2 | R31: 6.5 | S31: 6.5 | T31: 7 | U31: ='[1]Team Sanjay'!C7 -> 7 | Y31: =SUM(E31:X31) -> 61.19 | Z31: =IFERROR(AVERAGE(E31:X31),"-") -> 7.64875 | AB31: =AB30+1 -> 12 | AC31: {=INDEX(_xlfn.SORTBY($B$20:$B$35,IF(ISNUMBER($Z$20:$Z$35),$Z$20:$Z$35,-1),-1,$Y$20:$Y$35,-1),$AB31)} -> Aayush Puri | AD31: =INDEX($D$20:$D$35,MATCH($AC31,$B$20:$B$35,0)) -> SE | AE31: =COUNT(INDEX($E$20:$X$35,MATCH($AC31,$B$20:$B$35,0),0)) -> 8 | AF31: =INDEX($Y$20:$Y$35,MATCH($AC31,$B$20:$B$35,0)) -> 61.19 | AG31: =INDEX($Z$20:$Z$35,MATCH($AC31,$B$20:$B$35,0)) -> 7.64875 | AH31: =RANK(AG31,$AG$4:$AG$57,0) -> 32 | AJ31: =AJ30+1 -> 12 | AK31: {=INDEX(_xlfn.SORTBY($B$20:$B$35,IF(ISNUMBER($AR$20:$AR$35),$AR$20:$AR$35,-1),-1,$AS$20:$AS$35,-1),$AJ31)} -> Anish Gho Shrestha | AL31: =INDEX($D$20:$D$35,MATCH($AK31,$B$20:$B$35,0)) -> SE | AM31: =INDEX($C$20:$C$35,MATCH($AK31,$B$20:$B$35,0)) -> Team Bimal | AN31: =INDEX($AS$20:$AS$35,MATCH($AK31,$B$20:$B$35,0)) -> 6 | AO31: =INDEX($AR$20:$AR$35,MATCH($AK31,$B$20:$B$35,0)) -> 8.12 | AP31: =IF(ISNUMBER(AO31),RANK(AO31,$AO$4:$AO$57,0),"-") -> 34 | AR31: =IF(ISNUMBER($A31),IFERROR(AVERAGE(INDEX($E31:$X31,MATCH(Sheet1!$G$3,$E$1:$X$1,0)):INDEX($E31:$X31,MATCH(Sheet1!$G$2,$E$1:$X$1,0))),"-"),"") -> 7.4216667 | AS31: =IF(ISNUMBER($A31),COUNT(INDEX($E31:$X31,MATCH(Sheet1!$G$3,$E$1:$X$1,0)):INDEX($E31:$X31,MATCH(Sheet1!$G$2,$E$1:$X$1,0))),"") -> 6
A32: 13 | B32: Prajjwal Pandey | C32: Team Sanjay | D32: SE | E32: N/A | F32: N/A | G32: N/A | H32: N/A | I32: N/A | J32: N/A | K32: N/A | L32: N/A | M32: N/A | N32: N/A | O32: 6 | P32: 9.2 | Q32: 9 | R32: 8.33 | S32: 7 | T32: 8.67 | U32: ='[1]Team Sanjay'!C4 -> 8.33 | Y32: =SUM(E32:X32) -> 56.53 | Z32: =IFERROR(AVERAGE(E32:X32),"-") -> 8.0757143 | AB32: =AB31+1 -> 13 | AC32: {=INDEX(_xlfn.SORTBY($B$20:$B$35,IF(ISNUMBER($Z$20:$Z$35),$Z$20:$Z$35,-1),-1,$Y$20:$Y$35,-1),$AB32)} -> Aashish Katwal | AD32: =INDEX($D$20:$D$35,MATCH($AC32,$B$20:$B$35,0)) -> SE | AE32: =COUNT(INDEX($E$20:$X$35,MATCH($AC32,$B$20:$B$35,0),0)) -> 17 | AF32: =INDEX($Y$20:$Y$35,MATCH($AC32,$B$20:$B$35,0)) -> 128.89 | AG32: =INDEX($Z$20:$Z$35,MATCH($AC32,$B$20:$B$35,0)) -> 7.5817647 | AH32: =RANK(AG32,$AG$4:$AG$57,0) -> 35 | AJ32: =AJ31+1 -> 13 | AK32: {=INDEX(_xlfn.SORTBY($B$20:$B$35,IF(ISNUMBER($AR$20:$AR$35),$AR$20:$AR$35,-1),-1,$AS$20:$AS$35,-1),$AJ32)} -> Agrim Paneru | AL32: =INDEX($D$20:$D$35,MATCH($AK32,$B$20:$B$35,0)) -> SE | AM32: =INDEX($C$20:$C$35,MATCH($AK32,$B$20:$B$35,0)) -> AI Team | AN32: =INDEX($AS$20:$AS$35,MATCH($AK32,$B$20:$B$35,0)) -> 6 | AO32: =INDEX($AR$20:$AR$35,MATCH($AK32,$B$20:$B$35,0)) -> 7.985 | AP32: =IF(ISNUMBER(AO32),RANK(AO32,$AO$4:$AO$57,0),"-") -> 35 | AR32: =IF(ISNUMBER($A32),IFERROR(AVERAGE(INDEX($E32:$X32,MATCH(Sheet1!$G$3,$E$1:$X$1,0)):INDEX($E32:$X32,MATCH(Sheet1!$G$2,$E$1:$X$1,0))),"-"),"") -> 8.4216667 | AS32: =IF(ISNUMBER($A32),COUNT(INDEX($E32:$X32,MATCH(Sheet1!$G$3,$E$1:$X$1,0)):INDEX($E32:$X32,MATCH(Sheet1!$G$2,$E$1:$X$1,0))),"") -> 6
A33: 14 | B33: Agrim Paneru | C33: AI Team | D33: SE | E33: N/A | F33: N/A | G33: N/A | H33: N/A | I33: N/A | J33: N/A | K33: N/A | L33: N/A | M33: N/A | N33: N/A | O33: N/A | P33: 7 | Q33: 7 | R33: 8.2 | S33: 7.31 | T33: 9.2 | U33: ='[1]AI Team'!C3 -> 9.2 | Y33: =SUM(P33:X33) -> 47.91 | Z33: =IFERROR(AVERAGE(E33:X33),"-") -> 7.985 | AB33: =AB32+1 -> 14 | AC33: {=INDEX(_xlfn.SORTBY($B$20:$B$35,IF(ISNUMBER($Z$20:$Z$35),$Z$20:$Z$35,-1),-1,$Y$20:$Y$35,-1),$AB33)} -> Ankit Belal | AD33: =INDEX($D$20:$D$35,MATCH($AC33,$B$20:$B$35,0)) -> SE | AE33: =COUNT(INDEX($E$20:$X$35,MATCH($AC33,$B$20:$B$35,0),0)) -> 14 | AF33: =INDEX($Y$20:$Y$35,MATCH($AC33,$B$20:$B$35,0)) -> 103.39 | AG33: =INDEX($Z$20:$Z$35,MATCH($AC33,$B$20:$B$35,0)) -> 7.385 | AH33: =RANK(AG33,$AG$4:$AG$57,0) -> 36 | AJ33: =AJ32+1 -> 14 | AK33: {=INDEX(_xlfn.SORTBY($B$20:$B$35,IF(ISNUMBER($AR$20:$AR$35),$AR$20:$AR$35,-1),-1,$AS$20:$AS$35,-1),$AJ33)} -> Suyog Acharya | AL33: =INDEX($D$20:$D$35,MATCH($AK33,$B$20:$B$35,0)) -> SE | AM33: =INDEX($C$20:$C$35,MATCH($AK33,$B$20:$B$35,0)) -> Blaze Warrior | AN33: =INDEX($AS$20:$AS$35,MATCH($AK33,$B$20:$B$35,0)) -> 6 | AO33: =INDEX($AR$20:$AR$35,MATCH($AK33,$B$20:$B$35,0)) -> 7.8983333 | AP33: =IF(ISNUMBER(AO33),RANK(AO33,$AO$4:$AO$57,0),"-") -> 38 | AR33: =IF(ISNUMBER($A33),IFERROR(AVERAGE(INDEX($E33:$X33,MATCH(Sheet1!$G$3,$E$1:$X$1,0)):INDEX($E33:$X33,MATCH(Sheet1!$G$2,$E$1:$X$1,0))),"-"),"") -> 7.985 | AS33: =IF(ISNUMBER($A33),COUNT(INDEX($E33:$X33,MATCH(Sheet1!$G$3,$E$1:$X$1,0)):INDEX($E33:$X33,MATCH(Sheet1!$G$2,$E$1:$X$1,0))),"") -> 6
A34: 15 | B34: Anmol Chalise | C34: AI Team | D34: SE | E34: N/A | F34: N/A | G34: N/A | H34: N/A | I34: N/A | J34: N/A | K34: N/A | L34: N/A | M34: N/A | N34: N/A | O34: N/A | P34: 8.33 | Q34: 6.5 | R34: 8.23 | S34: N/A | T34: N/A | U34: N/A | Y34: =SUM(P34:X34) -> 23.06 | Z34: =IFERROR(AVERAGE(E34:X34),"-") -> 7.6866667 | AB34: =AB33+1 -> 15 | AC34: {=INDEX(_xlfn.SORTBY($B$20:$B$35,IF(ISNUMBER($Z$20:$Z$35),$Z$20:$Z$35,-1),-1,$Y$20:$Y$35,-1),$AB34)} -> Anish Gho Shrestha | AD34: =INDEX($D$20:$D$35,MATCH($AC34,$B$20:$B$35,0)) -> SE | AE34: =COUNT(INDEX($E$20:$X$35,MATCH($AC34,$B$20:$B$35,0),0)) -> 17 | AF34: =INDEX($Y$20:$Y$35,MATCH($AC34,$B$20:$B$35,0)) -> 116.13 | AG34: =INDEX($Z$20:$Z$35,MATCH($AC34,$B$20:$B$35,0)) -> 6.8311765 | AH34: =RANK(AG34,$AG$4:$AG$57,0) -> 44 | AJ34: =AJ33+1 -> 15 | AK34: {=INDEX(_xlfn.SORTBY($B$20:$B$35,IF(ISNUMBER($AR$20:$AR$35),$AR$20:$AR$35,-1),-1,$AS$20:$AS$35,-1),$AJ34)} -> Anmol Chalise | AL34: =INDEX($D$20:$D$35,MATCH($AK34,$B$20:$B$35,0)) -> SE | AM34: =INDEX($C$20:$C$35,MATCH($AK34,$B$20:$B$35,0)) -> AI Team | AN34: =INDEX($AS$20:$AS$35,MATCH($AK34,$B$20:$B$35,0)) -> 3 | AO34: =INDEX($AR$20:$AR$35,MATCH($AK34,$B$20:$B$35,0)) -> 7.6866667 | AP34: =IF(ISNUMBER(AO34),RANK(AO34,$AO$4:$AO$57,0),"-") -> 44 | AR34: =IF(ISNUMBER($A34),IFERROR(AVERAGE(INDEX($E34:$X34,MATCH(Sheet1!$G$3,$E$1:$X$1,0)):INDEX($E34:$X34,MATCH(Sheet1!$G$2,$E$1:$X$1,0))),"-"),"") -> 7.6866667 | AS34: =IF(ISNUMBER($A34),COUNT(INDEX($E34:$X34,MATCH(Sheet1!$G$3,$E$1:$X$1,0)):INDEX($E34:$X34,MATCH(Sheet1!$G$2,$E$1:$X$1,0))),"") -> 3
A35: 16 | B35: Mandip Thapa | C35: DevOps | D35: SE | E35: N/A | F35: N/A | G35: N/A | H35: N/A | I35: N/A | J35: N/A | K35: N/A | L35: N/A | M35: N/A | N35: N/A | O35: N/A | P35: N/A | Q35: N/A | R35: N/A | S35: N/A | T35: N/A | U35: =[1]DevOps!C6 -> 9 | Y35: =SUM(E35:X35) -> 9 | Z35: =IFERROR(AVERAGE(E35:X35),"-") -> 9 | AB35: =AB34+1 -> 16 | AC35: {=INDEX(_xlfn.SORTBY($B$20:$B$35,IF(ISNUMBER($Z$20:$Z$35),$Z$20:$Z$35,-1),-1,$Y$20:$Y$35,-1),$AB35)} -> Suyog Acharya | AD35: =INDEX($D$20:$D$35,MATCH($AC35,$B$20:$B$35,0)) -> SE | AE35: =COUNT(INDEX($E$20:$X$35,MATCH($AC35,$B$20:$B$35,0),0)) -> 17 | AF35: =INDEX($Y$20:$Y$35,MATCH($AC35,$B$20:$B$35,0)) -> 115.42 | AG35: =INDEX($Z$20:$Z$35,MATCH($AC35,$B$20:$B$35,0)) -> 6.7894118 | AH35: =RANK(AG35,$AG$4:$AG$57,0) -> 47 | AJ35: =AJ34+1 -> 16 | AK35: {=INDEX(_xlfn.SORTBY($B$20:$B$35,IF(ISNUMBER($AR$20:$AR$35),$AR$20:$AR$35,-1),-1,$AS$20:$AS$35,-1),$AJ35)} -> Aayush Puri | AL35: =INDEX($D$20:$D$35,MATCH($AK35,$B$20:$B$35,0)) -> SE | AM35: =INDEX($C$20:$C$35,MATCH($AK35,$B$20:$B$35,0)) -> Team Sanjay | AN35: =INDEX($AS$20:$AS$35,MATCH($AK35,$B$20:$B$35,0)) -> 6 | AO35: =INDEX($AR$20:$AR$35,MATCH($AK35,$B$20:$B$35,0)) -> 7.4216667 | AP35: =IF(ISNUMBER(AO35),RANK(AO35,$AO$4:$AO$57,0),"-") -> 46 | AR35: =IF(ISNUMBER($A35),IFERROR(AVERAGE(INDEX($E35:$X35,MATCH(Sheet1!$G$3,$E$1:$X$1,0)):INDEX($E35:$X35,MATCH(Sheet1!$G$2,$E$1:$X$1,0))),"-"),"") -> 9 | AS35: =IF(ISNUMBER($A35),COUNT(INDEX($E35:$X35,MATCH(Sheet1!$G$3,$E$1:$X$1,0)):INDEX($E35:$X35,MATCH(Sheet1!$G$2,$E$1:$X$1,0))),"") -> 1
AR36: =IF(ISNUMBER($A36),IFERROR(AVERAGE(INDEX($E36:$X36,MATCH(Sheet1!$G$3,$E$1:$X$1,0)):INDEX($E36:$X36,MATCH(Sheet1!$G$2,$E$1:$X$1,0))),"-"),"") | AS36: =IF(ISNUMBER($A36),COUNT(INDEX($E36:$X36,MATCH(Sheet1!$G$3,$E$1:$X$1,0)):INDEX($E36:$X36,MATCH(Sheet1!$G$2,$E$1:$X$1,0))),"")
B37: ASE | AB37: ASE | AJ37: ASE | AR37: =IF(ISNUMBER($A37),IFERROR(AVERAGE(INDEX($E37:$X37,MATCH(Sheet1!$G$3,$E$1:$X$1,0)):INDEX($E37:$X37,MATCH(Sheet1!$G$2,$E$1:$X$1,0))),"-"),"") | AS37: =IF(ISNUMBER($A37),COUNT(INDEX($E37:$X37,MATCH(Sheet1!$G$3,$E$1:$X$1,0)):INDEX($E37:$X37,MATCH(Sheet1!$G$2,$E$1:$X$1,0))),"")
A38: 1 | B38: Diplov Khatri | C38: Run Team | D38: ASE | E38: 6.36 | F38: 8.67 | G38: 3.5 | H38: 5.4 | I38: 6.43 | J38: 6.6 | K38: 6.5 | L38: 8.67 | M38: N/A | N38: 9.4 | O38: 8.33 | P38: 9.4 | Q38: 8.33 | R38: 8.33 | S38: 8.95 | T38: 8.67 | U38: ='[1]Run Team'!C3 -> 8.33 | Y38: =SUM(E38:X38) -> 121.87 | Z38: =IFERROR(AVERAGE(E38:X38),"-") -> 7.616875 | AB38: 1 | AC38: {=INDEX(_xlfn.SORTBY($B$38:$B$57,IF(ISNUMBER($Z$38:$Z$57),$Z$38:$Z$57,-1),-1,$Y$38:$Y$57,-1),$AB38)} -> Dilendra Thagunna | AD38: =INDEX($D$38:$D$57,MATCH($AC38,$B$38:$B$57,0)) -> ASE | AE38: =COUNT(INDEX($E$38:$X$57,MATCH($AC38,$B$38:$B$57,0),0)) -> 1 | AF38: =INDEX($Y$38:$Y$57,MATCH($AC38,$B$38:$B$57,0)) -> 10 | AG38: =INDEX($Z$38:$Z$57,MATCH($AC38,$B$38:$B$57,0)) -> 10 | AH38: =RANK(AG38,$AG$4:$AG$57,0) -> 1 | AJ38: 1 | AK38: {=INDEX(_xlfn.SORTBY($B$38:$B$57,IF(ISNUMBER($AR$38:$AR$57),$AR$38:$AR$57,-1),-1,$AS$38:$AS$57,-1),$AJ38)} -> Dilendra Thagunna | AL38: =INDEX($D$38:$D$57,MATCH($AK38,$B$38:$B$57,0)) -> ASE | AM38: =INDEX($C$38:$C$57,MATCH($AK38,$B$38:$B$57,0)) -> AI Team | AN38: =INDEX($AS$38:$AS$57,MATCH($AK38,$B$38:$B$57,0)) -> 1 | AO38: =INDEX($AR$38:$AR$57,MATCH($AK38,$B$38:$B$57,0)) -> 10 | AP38: =IF(ISNUMBER(AO38),RANK(AO38,$AO$4:$AO$57,0),"-") -> 1 | AR38: =IF(ISNUMBER($A38),IFERROR(AVERAGE(INDEX($E38:$X38,MATCH(Sheet1!$G$3,$E$1:$X$1,0)):INDEX($E38:$X38,MATCH(Sheet1!$G$2,$E$1:$X$1,0))),"-"),"") -> 8.6683333 | AS38: =IF(ISNUMBER($A38),COUNT(INDEX($E38:$X38,MATCH(Sheet1!$G$3,$E$1:$X$1,0)):INDEX($E38:$X38,MATCH(Sheet1!$G$2,$E$1:$X$1,0))),"") -> 6
A39: 2 | B39: Ramita Shrestha | C39: Team Bimal | D39: ASE | E39: N/A | F39: N/A | G39: N/A | H39: N/A | I39: N/A | J39: 7.85 | K39: 6.5 | L39: 7.67 | M39: 7 | N39: 7 | O39: 9.6 | P39: 9.4 | Q39: 9.2 | R39: 9 | S39: 9.6 | T39: 9.2 | U39: ='[1]Team Bimal'!C2 -> 8.33 | Y39: =SUM(E39:X39) -> 100.35 | Z39: =IFERROR(AVERAGE(E39:X39),"-") -> 8.3625 | AB39: =AB38+1 -> 2 | AC39: {=INDEX(_xlfn.SORTBY($B$38:$B$57,IF(ISNUMBER($Z$38:$Z$57),$Z$38:$Z$57,-1),-1,$Y$38:$Y$57,-1),$AB39)} -> Ashika Balami | AD39: =INDEX($D$38:$D$57,MATCH($AC39,$B$38:$B$57,0)) -> ASE | AE39: =COUNT(INDEX($E$38:$X$57,MATCH($AC39,$B$38:$B$57,0),0)) -> 1 | AF39: =INDEX($Y$38:$Y$57,MATCH($AC39,$B$38:$B$57,0)) -> 9.8 | AG39: =INDEX($Z$38:$Z$57,MATCH($AC39,$B$38:$B$57,0)) -> 9.8 | AH39: =RANK(AG39,$AG$4:$AG$57,0) -> 2 | AJ39: =AJ38+1 -> 2 | AK39: {=INDEX(_xlfn.SORTBY($B$38:$B$57,IF(ISNUMBER($AR$38:$AR$57),$AR$38:$AR$57,-1),-1,$AS$38:$AS$57,-1),$AJ39)} -> Ashika Balami | AL39: =INDEX($D$38:$D$57,MATCH($AK39,$B$38:$B$57,0)) -> ASE | AM39: =INDEX($C$38:$C$57,MATCH($AK39,$B$38:$B$57,0)) -> Team Bravo | AN39: =INDEX($AS$38:$AS$57,MATCH($AK39,$B$38:$B$57,0)) -> 1 | AO39: =INDEX($AR$38:$AR$57,MATCH($AK39,$B$38:$B$57,0)) -> 9.8 | AP39: =IF(ISNUMBER(AO39),RANK(AO39,$AO$4:$AO$57,0),"-") -> 2 | AR39: =IF(ISNUMBER($A39),IFERROR(AVERAGE(INDEX($E39:$X39,MATCH(Sheet1!$G$3,$E$1:$X$1,0)):INDEX($E39:$X39,MATCH(Sheet1!$G$2,$E$1:$X$1,0))),"-"),"") -> 9.1216667 | AS39: =IF(ISNUMBER($A39),COUNT(INDEX($E39:$X39,MATCH(Sheet1!$G$3,$E$1:$X$1,0)):INDEX($E39:$X39,MATCH(Sheet1!$G$2,$E$1:$X$1,0))),"") -> 6
A40: 3 | B40: Niva Awale | C40: Team Dhangadhi | D40: ASE | E40: N/A | F40: N/A | G40: N/A | H40: N/A | I40: N/A | J40: 7.9 | K40: 6.6 | L40: 7 | M40: 6.5 | N40: 8.5 | O40: 9.8 | P40: 10 | Q40: 9 | R40: 8.83 | S40: 7 | T40: 6.5 | U40: ='[1]Team Bikash'!C3 -> 6.5 | Y40: =SUM(E40:X40) -> 94.13 | Z40: =IFERROR(AVERAGE(E40:X40),"-") -> 7.8441667 | AB40: =AB39+1 -> 3 | AC40: {=INDEX(_xlfn.SORTBY($B$38:$B$57,IF(ISNUMBER($Z$38:$Z$57),$Z$38:$Z$57,-1),-1,$Y$38:$Y$57,-1),$AB40)} -> Dipesh Kayastha | AD40: =INDEX($D$38:$D$57,MATCH($AC40,$B$38:$B$57,0)) -> ASE | AE40: =COUNT(INDEX($E$38:$X$57,MATCH($AC40,$B$38:$B$57,0),0)) -> 1 | AF40: =INDEX($Y$38:$Y$57,MATCH($AC40,$B$38:$B$57,0)) -> 9.8 | AG40: =INDEX($Z$38:$Z$57,MATCH($AC40,$B$38:$B$57,0)) -> 9.8 | AH40: =RANK(AG40,$AG$4:$AG$57,0) -> 2 | AJ40: =AJ39+1 -> 3 | AK40: {=INDEX(_xlfn.SORTBY($B$38:$B$57,IF(ISNUMBER($AR$38:$AR$57),$AR$38:$AR$57,-1),-1,$AS$38:$AS$57,-1),$AJ40)} -> Dipesh Kayastha | AL40: =INDEX($D$38:$D$57,MATCH($AK40,$B$38:$B$57,0)) -> ASE | AM40: =INDEX($C$38:$C$57,MATCH($AK40,$B$38:$B$57,0)) -> Team Sanjay | AN40: =INDEX($AS$38:$AS$57,MATCH($AK40,$B$38:$B$57,0)) -> 1 | AO40: =INDEX($AR$38:$AR$57,MATCH($AK40,$B$38:$B$57,0)) -> 9.8 | AP40: =IF(ISNUMBER(AO40),RANK(AO40,$AO$4:$AO$57,0),"-") -> 2 | AR40: =IF(ISNUMBER($A40),IFERROR(AVERAGE(INDEX($E40:$X40,MATCH(Sheet1!$G$3,$E$1:$X$1,0)):INDEX($E40:$X40,MATCH(Sheet1!$G$2,$E$1:$X$1,0))),"-"),"") -> 7.9716667 | AS40: =IF(ISNUMBER($A40),COUNT(INDEX($E40:$X40,MATCH(Sheet1!$G$3,$E$1:$X$1,0)):INDEX($E40:$X40,MATCH(Sheet1!$G$2,$E$1:$X$1,0))),"") -> 6
...

Sheet Performance Insights
A1: Performance & Ranking Insights
A2: Live view of all numeric sprint scores on the Compile Sheet (RUN and N/A excluded). Updates automatically as new sprints are entered.
A4: Resources | B4: Overall Avg | C4: Latest Sprint | D4: Latest Sprint Avg | E4: Latest Coverage | F4: Min Sprints for Top 10
A5: =COUNT('Compile Sheet '!$Z$4:$Z$57) -> 49 | B5: =SUM('Compile Sheet '!$Y$4:$Y$57)/SUM('Compile Sheet '!$AE$4:$AE$57) -> 7.7769732 | C5: {=_xlfn.XLOOKUP(TRUE,$O$10:$O$29>0,$M$10:$M$29,"-",0,-1)} -> S138 | D5: =_xlfn.XLOOKUP(C5,$M$10:$M$29,$N$10:$N$29,"-") -> 8.4085106 | E5: =_xlfn.XLOOKUP(C5,$M$10:$M$29,$O$10:$O$29,0)/A5 -> 0.95918367 | F5: 5
A8: Team Summary | H8: Designation Summary | M8: Sprint Trend
A9: Team | B9: People | C9: Score Obs | D9: Total Score | E9: Weighted Avg | F9: Rank | H9: Designation | I9: People | J9: Score Obs | K9: Weighted Avg | M9: Sprint | N9: Average | O9: Participants
A10: DevOps | B10: =COUNTIF('Compile Sheet '!$C$4:$C$57,$A10) -> 7 | C10: {=SUMPRODUCT(('Compile Sheet '!$C$4:$C$57=$A10)*ISNUMBER('Compile Sheet '!$E$4:$X$57))} -> 41 | D10: =SUMIF('Compile Sheet '!$C$4:$C$57,$A10,'Compile Sheet '!$Y$4:$Y$57) -> 367.91 | E10: =IFERROR(D10/C10,0) -> 8.9734146 | F10: =RANK(E10,$E$10:$E$17,0) -> 1 | H10: Team Lead | I10: =COUNTIF('Compile Sheet '!$D$4:$D$57,$H10) -> 6 | J10: {=SUMPRODUCT(('Compile Sheet '!$D$4:$D$57=$H10)*ISNUMBER('Compile Sheet '!$E$4:$X$57))} -> 83 | K10: =IFERROR(SUMIF('Compile Sheet '!$D$4:$D$57,$H10,'Compile Sheet '!$Y$4:$Y$57)/J10,0) -> 8.0404819 | M10: {=INDEX('Compile Sheet '!$E$1:$X$1,ROWS($M$10:M10))} -> S122 | N10: =IFERROR(AVERAGEIFS(INDEX('Compile Sheet '!$E$4:$X$57,0,ROWS($M$10:M10)),'Compile Sheet '!$B$4:$B$57,"<>"),"-") -> 6.831087 | O10: =COUNTIFS(INDEX('Compile Sheet '!$E$4:$X$57,0,ROWS($M$10:M10)),">=0",'Compile Sheet '!$B$4:$B$57,"<>") -> 23
A11: Run Team | B11: =COUNTIF('Compile Sheet '!$C$4:$C$57,$A11) -> 5 | C11: {=SUMPRODUCT(('Compile Sheet '!$C$4:$C$57=$A11)*ISNUMBER('Compile Sheet '!$E$4:$X$57))} -> 70 | D11: =SUMIF('Compile Sheet '!$C$4:$C$57,$A11,'Compile Sheet '!$Y$4:$Y$57) -> 571.2 | E11: =IFERROR(D11/C11,0) -> 8.16 | F11: =RANK(E11,$E$10:$E$17,0) -> 2 | H11: SSE | I11: =COUNTIF('Compile Sheet '!$D$4:$D$57,$H11) -> 7 | J11: {=SUMPRODUCT(('Compile Sheet '!$D$4:$D$57=$H11)*ISNUMBER('Compile Sheet '!$E$4:$X$57))} -> 92 | K11: =IFERROR(SUMIF('Compile Sheet '!$D$4:$D$57,$H11,'Compile Sheet '!$Y$4:$Y$57)/J11,0) -> 7.8157609 | M11: {=INDEX('Compile Sheet '!$E$1:$X$1,ROWS($M$10:M11))} -> S123 | N11: =IFERROR(AVERAGEIFS(INDEX('Compile Sheet '!$E$4:$X$57,0,ROWS($M$10:M11)),'Compile Sheet '!$B$4:$B$57,"<>"),"-") -> 7.2191667 | O11: =COUNTIFS(INDEX('Compile Sheet '!$E$4:$X$57,0,ROWS($M$10:M11)),">=0",'Compile Sheet '!$B$4:$B$57,"<>") -> 24
A12: Team Bravo | B12: =COUNTIF('Compile Sheet '!$C$4:$C$57,$A12) -> 8 | C12: {=SUMPRODUCT(('Compile Sheet '!$C$4:$C$57=$A12)*ISNUMBER('Compile Sheet '!$E$4:$X$57))} -> 107 | D12: =SUMIF('Compile Sheet '!$C$4:$C$57,$A12,'Compile Sheet '!$Y$4:$Y$57) -> 855.59 | E12: =IFERROR(D12/C12,0) -> 7.9961682 | F12: =RANK(E12,$E$10:$E$17,0) -> 4 | H12: SE | I12: =COUNTIF('Compile Sheet '!$D$4:$D$57,$H12) -> 16 | J12: {=SUMPRODUCT(('Compile Sheet '!$D$4:$D$57=$H12)*ISNUMBER('Compile Sheet '!$E$4:$X$57))} -> 188 | K12: =IFERROR(SUMIF('Compile Sheet '!$D$4:$D$57,$H12,'Compile Sheet '!$Y$4:$Y$57)/J12,0) -> 7.7851596 | M12: {=INDEX('Compile Sheet '!$E$1:$X$1,ROWS($M$10:M12))} -> S124 | N12: =IFERROR(AVERAGEIFS(INDEX('Compile Sheet '!$E$4:$X$57,0,ROWS($M$10:M12)),'Compile Sheet '!$B$4:$B$57,"<>"),"-") -> 6.1569565 | O12: =COUNTIFS(INDEX('Compile Sheet '!$E$4:$X$57,0,ROWS($M$10:M12)),">=0",'Compile Sheet '!$B$4:$B$57,"<>") -> 23
A13: Team Sanjay | B13: =COUNTIF('Compile Sheet '!$C$4:$C$57,$A13) -> 6 | C13: {=SUMPRODUCT(('Compile Sheet '!$C$4:$C$57=$A13)*ISNUMBER('Compile Sheet '!$E$4:$X$57))} -> 57 | D13: =SUMIF('Compile Sheet '!$C$4:$C$57,$A13,'Compile Sheet '!$Y$4:$Y$57) -> 436.79 | E13: =IFERROR(D13/C13,0) -> 7.6629825 | F13: =RANK(E13,$E$10:$E$17,0) -> 5 | H13: ASE | I13: =COUNTIF('Compile Sheet '!$D$4:$D$57,$H13) -> 20 | J13: {=SUMPRODUCT(('Compile Sheet '!$D$4:$D$57=$H13)*ISNUMBER('Compile Sheet '!$E$4:$X$57))} -> 197 | K13: =IFERROR(SUMIF('Compile Sheet '!$D$4:$D$57,$H13,'Compile Sheet '!$Y$4:$Y$57)/J13,0) -> 7.6400254 | M13: {=INDEX('Compile Sheet '!$E$1:$X$1,ROWS($M$10:M13))} -> S125 | N13: =IFERROR(AVERAGEIFS(INDEX('Compile Sheet '!$E$4:$X$57,0,ROWS($M$10:M13)),'Compile Sheet '!$B$4:$B$57,"<>"),"-") -> 6.9391304 | O13: =COUNTIFS(INDEX('Compile Sheet '!$E$4:$X$57,0,ROWS($M$10:M13)),">=0",'Compile Sheet '!$B$4:$B$57,"<>") -> 23
A14: Team Bimal | B14: =COUNTIF('Compile Sheet '!$C$4:$C$57,$A14) -> 7 | C14: {=SUMPRODUCT(('Compile Sheet '!$C$4:$C$57=$A14)*ISNUMBER('Compile Sheet '!$E$4:$X$57))} -> 86 | D14: =SUMIF('Compile Sheet '!$C$4:$C$57,$A14,'Compile Sheet '!$Y$4:$Y$57) -> 657.74 | E14: =IFERROR(D14/C14,0) -> 7.6481395 | F14: =RANK(E14,$E$10:$E$17,0) -> 6 | M14: {=INDEX('Compile Sheet '!$E$1:$X$1,ROWS($M$10:M14))} -> S126 | N14: =IFERROR(AVERAGEIFS(INDEX('Compile Sheet '!$E$4:$X$57,0,ROWS($M$10:M14)),'Compile Sheet '!$B$4:$B$57,"<>"),"-") -> 7.1620833 | O14: =COUNTIFS(INDEX('Compile Sheet '!$E$4:$X$57,0,ROWS($M$10:M14)),">=0",'Compile Sheet '!$B$4:$B$57,"<>") -> 24
A15: AI Team | B15: =COUNTIF('Compile Sheet '!$C$4:$C$57,$A15) -> 3 | C15: {=SUMPRODUCT(('Compile Sheet '!$C$4:$C$57=$A15)*ISNUMBER('Compile Sheet '!$E$4:$X$57))} -> 10 | D15: =SUMIF('Compile Sheet '!$C$4:$C$57,$A15,'Compile Sheet '!$Y$4:$Y$57) -> 80.97 | E15: =IFERROR(D15/C15,0) -> 8.097 | F15: =RANK(E15,$E$10:$E$17,0) -> 3 | M15: {=INDEX('Compile Sheet '!$E$1:$X$1,ROWS($M$10:M15))} -> S127 | N15: =IFERROR(AVERAGEIFS(INDEX('Compile Sheet '!$E$4:$X$57,0,ROWS($M$10:M15)),'Compile Sheet '!$B$4:$B$57,"<>"),"-") -> 6.9 | O15: =COUNTIFS(INDEX('Compile Sheet '!$E$4:$X$57,0,ROWS($M$10:M15)),">=0",'Compile Sheet '!$B$4:$B$57,"<>") -> 27
A16: Blaze Warrior | B16: =COUNTIF('Compile Sheet '!$C$4:$C$57,$A16) -> 6 | C16: {=SUMPRODUCT(('Compile Sheet '!$C$4:$C$57=$A16)*ISNUMBER('Compile Sheet '!$E$4:$X$57))} -> 102 | D16: =SUMIF('Compile Sheet '!$C$4:$C$57,$A16,'Compile Sheet '!$Y$4:$Y$57) -> 763.31 | E16: =IFERROR(D16/C16,0) -> 7.4834314 | F16: =RANK(E16,$E$10:$E$17,0) -> 7 | M16: {=INDEX('Compile Sheet '!$E$1:$X$1,ROWS($M$10:M16))} -> S128 | N16: =IFERROR(AVERAGEIFS(INDEX('Compile Sheet '!$E$4:$X$57,0,ROWS($M$10:M16)),'Compile Sheet '!$B$4:$B$57,"<>"),"-") -> 6.5281481 | O16: =COUNTIFS(INDEX('Compile Sheet '!$E$4:$X$57,0,ROWS($M$10:M16)),">=0",'Compile Sheet '!$B$4:$B$57,"<>") -> 27
A17: Team Dhangadhi | B17: =COUNTIF('Compile Sheet '!$C$4:$C$57,$A17) -> 7 | C17: {=SUMPRODUCT(('Compile Sheet '!$C$4:$C$57=$A17)*ISNUMBER('Compile Sheet '!$E$4:$X$57))} -> 87 | D17: =SUMIF('Compile Sheet '!$C$4:$C$57,$A17,'Compile Sheet '!$Y$4:$Y$57) -> 621.595 | E17: =IFERROR(D17/C17,0) -> 7.1447701 | F17: =RANK(E17,$E$10:$E$17,0) -> 8 | M17: {=INDEX('Compile Sheet '!$E$1:$X$1,ROWS($M$10:M17))} -> S129 | N17: =IFERROR(AVERAGEIFS(INDEX('Compile Sheet '!$E$4:$X$57,0,ROWS($M$10:M17)),'Compile Sheet '!$B$4:$B$57,"<>"),"-") -> 7.11 | O17: =COUNTIFS(INDEX('Compile Sheet '!$E$4:$X$57,0,ROWS($M$10:M17)),">=0",'Compile Sheet '!$B$4:$B$57,"<>") -> 32
M18: {=INDEX('Compile Sheet '!$E$1:$X$1,ROWS($M$10:M18))} -> S130 | N18: =IFERROR(AVERAGEIFS(INDEX('Compile Sheet '!$E$4:$X$57,0,ROWS($M$10:M18)),'Compile Sheet '!$B$4:$B$57,"<>"),"-") -> 6.598 | O18: =COUNTIFS(INDEX('Compile Sheet '!$E$4:$X$57,0,ROWS($M$10:M18)),">=0",'Compile Sheet '!$B$4:$B$57,"<>") -> 30
A19: Top 10 Performers (min sprints per F5) | M19: {=INDEX('Compile Sheet '!$E$1:$X$1,ROWS($M$10:M19))} -> S131 | N19: =IFERROR(AVERAGEIFS(INDEX('Compile Sheet '!$E$4:$X$57,0,ROWS($M$10:M19)),'Compile Sheet '!$B$4:$B$57,"<>"),"-") -> 8.3016216 | O19: =COUNTIFS(INDEX('Compile Sheet '!$E$4:$X$57,0,ROWS($M$10:M19)),">=0",'Compile Sheet '!$B$4:$B$57,"<>") -> 37
